Workbook
Name REPORT_DATE: '本日の日報'!$B$5

Sheet 使い方
A1: 日報・日次決算テンプレート（年商1000億円への10年計画）
A2: 毎日、日報・営業実績・日次決算・日課チェックを1枚に入力して提出し、日次ログにためる。月次集計と10年計画は、ためたデータから自動で集計される。
A4: 毎日の流れ
A5: 1. 朝 | B5: 「本日の日報」で日付を確認し、前回決めた今日のTop3と売上目標を見る。「毎日やること」で今日の行動を決める。
A6: 2. 日中 | B6: 費用が出たら「経費ログ」に1件1行で記録する。商談が動いたら「案件パイプライン」のフェーズと次のアクションを更新する。
A7: 3. 夜 | B7: 「本日の日報」の薄い黄色のセルに、売上・営業実績・日課の結果・振り返り（KPT）・明日のTop3を入力する。売上原価・販管費・利益は経費ログから自動で計算される。
A8: 4. 提出 | B8: メニュー「日報」→「本日の日報を提出」を押す（Apps Scriptの設定が必要。下記3）。スクリプトを使わない場合は「提出データ」シートの2行目をコピーし、「日次ログ」の最終行の下に値のみ貼り付け（Ctrl+Shift+V）。
A9: 5. 週に1回 | B9: 「月次集計」で売上・利益・日課の実行率を、「10年計画」で今年の目標との差を確認する。続かない日課は原因を1つ決めて手を打つ。
A11: セルの色
A12: 入力値 | B12: 薄い黄色：入力するセル（青い文字が入力した値）
A13: 計算値 | B13: 白：自動で計算されるセル（入力しない）
A14: 参照値 | B14: 緑の文字：ほかのシートから参照している値
A16: 最初に1回だけやること
A17: 1 | B17: 「設定」シートの薄い黄色のセル（計画開始日、1年目の売上目標、平均受注単価、受注率など）を自分の数字に書き換える。
A18: 2 | B18: 「毎日やること」の項目と目安を、自分の事業に合わせて見直す（本日の日報・日次ログ・月次集計に自動で反映される）。
A19: 3 | B19: 提出ボタンを使う場合は、メニュー「拡張機能」→「Apps Script」を開き、最初からあるコードを消して、提出スクリプト（Googleドライブの「日報 提出スクリプト（Apps Script用）」、またはGitHubの daily-report/gas/Code.gs）を貼り付けて保存する。シートを再読み込みするとメニューに「日報」が表示される。初回だけGoogleの承認画面が出るので、自分のアカウントで許可する。
A20: 4 | B20: 提出時にメールも送る場合は「設定」の提出先メールアドレスを入力する。毎晩の未提出リマインドは、メニュー「日報」→「毎日のリマインドを設定」。
A22: シートの一覧
A23: シート | B23: 役割 | C23: いつ入力するか
A24: 本日の日報 | B24: 毎日の入力画面。日報・営業実績・日次決算・日課チェック | C24: 毎日
A25: 毎日やること | B25: 年商1000億に向けて毎日やることの一覧と理由 | C25: 必要に応じて見直す
A26: 経費ログ | B26: 費用を1件1行で記録。日次決算と月次集計に反映 | C26: 費用が出たとき
A27: 案件パイプライン | B27: 案件ごとのフェーズ・見込金額・次のアクション | C27: 商談が動いたとき
A28: 月次集計 | B28: 月ごとの売上・利益・営業数字・日課の実行率 | C28: 見るだけ（表示する年目は変更可）
A29: 10年計画 | B29: 1〜10年目の売上目標と実績、必要な件数と人数の逆算 | C29: 見るだけ（重点テーマは書き換え可）
A30: 日次ログ | B30: 提出した日報が1日1行でたまる記録 | C30: 提出時に自動
A31: 提出データ | B31: 日次ログに送る1行分のデータ（自動作成） | C31: 触らない
A32: 設定 | B32: 目標・前提条件・選択肢のリスト | C32: 最初に1回（毎月見直す）
A34: 補足
A35: ・ | B35: 日次ログ・経費ログ・案件パイプラインの「記入例」の行は集計されない。不要なら行ごと削除してよい。
A36: ・ | B36: 経費は経費ログが正本。提出後に経費を追加・修正しても月次集計には反映される（日次ログの費用欄は提出時点の記録）。
A37: ・ | B37: 目標の数字（仮の値）は設定シートで変更できる。変更すると10年計画・本日の日報・月次集計が連動する。
A38: ・ | B38: 同じ日付の日報をもう一度提出すると、上書きするか確認が出る。

Sheet 本日の日報
A1: 本日の日報・日次決算
A2: 薄い黄色のセルに入力（青い文字）。白いセルは自動計算、緑の文字はほかのシートから参照。入力が終わったらメニュー「日報」→「本日の日報を提出」（スクリプトがない場合は「提出データ」シートの手順）。
A4: 1. 基本情報
A5: 日付 | B5: 46296 | C5: =IF(B5="","",CHOOSE(WEEKDAY(B5),"日","月","火","水","木","金","土")) | D5: 計画開始から | E5: =IF(B5="","",B5-'設定'!$B$5+1) | F5: Ctrl + ;（セミコロン）で今日の日付を入力できる
A6: 計画年目 | B6: =MIN(10,IFERROR(DATEDIF('設定'!$B$5,B5,"Y")+1,1)) | D6: 前回の提出日 | E6: =_xlfn.MAXIFS('日次ログ'!$A:$A,'日次ログ'!$A:$A,"<"&$B$5) | F6: 日次ログにある、この日付より前の最新の日報
A7: 体調（1〜5） | D7: 記入者 | E7: ='設定'!$B$13&"" | F7: 5＝絶好調、3＝普通、1＝不調
A8: 今日のテーマ（一言）
A10: 2. 今日のTop3（前回の日報で決めたこと）
A11: 項目 | B11: 結果（○△×） | C11: 内容（前回の日報から自動表示）
A12: ① 最重要 | C12: =IFERROR(INDEX('日次ログ'!$AV:$AV,MATCH($E$6,'日次ログ'!$A:$A,0))&"","")
A13: ② | C13: =IFERROR(INDEX('日次ログ'!$AW:$AW,MATCH($E$6,'日次ログ'!$A:$A,0))&"","")
A14: ③ | C14: =IFERROR(INDEX('日次ログ'!$AX:$AX,MATCH($E$6,'日次ログ'!$A:$A,0))&"","")
A15: Top3の実行率 | B15: =IF(COUNTIF(C12:C14,"?*")=0,0,COUNTIF(B12:B14,"○")/COUNTIF(C12:C14,"?*")) | C15: ○の数÷Top3の数。前回の日報がない日は「-」
A17: 3. 売上目標と進捗（年商1000億からの逆算）
A18: 項目 | B18: 実績 | C18: 単位 | D18: 目標 | E18: 達成率 | F18: メモ
A19: 今日の売上 | B19: =B38 | C19: 円 | D19: =D21/365 | E19: =IF(D19=0,0,B19/D19) | F19: 目標＝今年の売上目標÷365
A20: 今月の売上（本日まで） | B20: =SUMIFS('日次ログ'!$J:$J,'日次ログ'!$A:$A,">="&DATE(YEAR($B$5),MONTH($B$5),1),'日次ログ'!$A:$A,"<"&$B$5)+$B$38 | C20: 円 | D20: =D21/12 | E20: =IF(D20=0,0,B20/D20) | F20: 目標＝今年の売上目標÷12
A21: 今年の売上（本日まで） | B21: =SUMIFS('日次ログ'!$J:$J,'日次ログ'!$A:$A,">="&EDATE('設定'!$B$5,12*($B$6-1)),'日次ログ'!$A:$A,"<"&$B$5)+$B$38 | C21: 円 | D21: =INDEX('10年計画'!$D$10:$D$19,$B$6)*10^8 | E21: =IF(D21=0,0,B21/D21) | F21: ="計画"&$B$6&"年目の目標（10年計画シート）"
A22: 今月の目標まであと | B22: =MAX(0,D20-B20) | C22: 円 | F22: 今月の目標から今月の売上を引いた額
A23: 明日以降に必要な売上（1日あたり） | B23: =IF(EOMONTH($B$5,0)-$B$5<=0,0,B22/(EOMONTH($B$5,0)-$B$5)) | C23: 円 | F23: 残りの額を、月末までの残り日数で割った額
A25: 4. 営業実績（本日）
A26: 項目 | B26: 実績 | C26: 単位 | D26: 目標 | E26: 達成率 | F26: メモ
A27: 新規アプローチ数 | C27: 件 | D27: =INDEX('10年計画'!$L$10:$L$19,$B$6) | E27: =IF(D27=0,0,B27/D27) | F27: 架電・DM・訪問・紹介依頼など、見込み客との新しい接点。目標は10年計画の逆算
A28: アポ獲得数 | C28: 件
A29: 商談数（実施） | C29: 件 | D29: =INDEX('10年計画'!$J$10:$J$19,$B$6)/365 | E29: =IF(D29=0,0,B29/D29) | F29: 目標＝10年計画の年間必要商談数÷365
A30: 提案・見積の提出数 | C30: 件
A31: 受注数 | C31: 件 | D31: =INDEX('10年計画'!$I$10:$I$19,$B$6)/365 | E31: =IF(D31=0,0,B31/D31) | F31: 目標＝10年計画の年間必要受注件数÷365
A32: 受注金額 | C32: 円 | D32: =D19 | E32: =IF(D32=0,0,B32/D32) | F32: 契約した金額（売上の計上日とずれてもよい）
A33: 既存顧客との面談・連絡 | C33: 社 | D33: ='設定'!$B$12 | E33: =IF(D33=0,0,B33/D33) | F33: 毎日やることNo.5
A34: 紹介でもらった見込み客 | C34: 件
A36: 5. 日次決算（本日）
A37: 項目 | B37: 本日 | C37: 単位 | D37: 今月累計 | F37: メモ
A38: 売上高 | C38: 円 | D38: =B20 | F38: 本日計上した売上（税抜）
A39: 売上原価 | B39: =SUMIFS('経費ログ'!$D:$D,'経費ログ'!$A:$A,$B$5,'経費ログ'!$B:$B,"原価：*") | C39: 円 | D39: =SUMIFS('経費ログ'!$D:$D,'経費ログ'!$A:$A,">="&DATE(YEAR($B$5),MONTH($B$5),1),'経費ログ'!$A:$A,"<="&$B$5,'経費ログ'!$B:$B,"原価：*") | F39: 経費ログのうち、科目が「原価：」で始まる費用の合計
A40: 粗利 | B40: =B38-B39 | C40: 円 | D40: =D38-D39
A41: 粗利率 | B41: =IF(B38=0,0,B40/B38) | C41: ％ | D41: =IF(D38=0,0,D40/D38)
A42: 販管費 | B42: =SUMIFS('経費ログ'!$D:$D,'経費ログ'!$A:$A,$B$5)-B39 | C42: 円 | D42: =SUMIFS('経費ログ'!$D:$D,'経費ログ'!$A:$A,">="&DATE(YEAR($B$5),MONTH($B$5),1),'経費ログ'!$A:$A,"<="&$B$5)-D39 | F42: 経費ログのうち、原価以外の科目の合計
A43: 営業利益 | B43: =B40-B42 | C43: 円 | D43: =D40-D42
A44: 営業利益率 | B44: =IF(B38=0,0,B43/B38) | C44: ％ | D44: =IF(D38=0,0,D43/D38)
A45: 経費の記録件数 | B45: =COUNTIFS('経費ログ'!$A:$A,$B$5) | C45: 件 | F45: 費用は「経費ログ」に1件1行で入力。0件のときは記録漏れがないか確認
...

Sheet 毎日やること
A1: 年商1000億円（10年後）に向けて毎日やること
A2: ="10年目の目標 年"&TEXT('設定'!$B$7,"#,##0")&"億円は、1日あたり約"&TEXT('設定'!$B$7/365,"#,##0.0")&"億円。毎日の行動を下の16項目に分け、「本日の日報」で○△×をつける。"
A3: 項目名・短縮名・目安は自分の事業に合わせて書き換えてよい（本日の日報・日次ログ・月次集計に自動で反映される）。
A4: No | B4: 分類 | C4: 毎日やること | D4: 短縮名（ログ用） | E4: 具体的な行動 | F4: 目安 | G4: 1000億につながる理由
A5: 1 | B5: 数字 | C5: 目標から逆算して今日の数字を決める | D5: 逆算・目標確認 | E5: 10年計画→今年→今月の目標と実績の差を確認し、今日の売上と行動件数の目標を決める | F5: 朝5分 | G5: 10年目の目標を365で割ると、1日に必要な売上がわかる（年1000億円なら1日約2.7億円）。毎日差を確認しないと、差は月末まで気づかれないまま広がる
A6: 2 | B6: 数字 | C6: 日次決算を締める | D6: 日次決算 | E6: 今日の売上・原価・経費・現預金残高をその日のうちに確定し、日報で提出する | F6: 夜10分 | G6: 急成長中の会社は黒字でも資金が尽きることがある。利益と現金を毎日つかんでいれば、手を打つのが早くなる
A7: 3 | B7: 売上 | C7: 最重要タスクを午前中に終わらせる | D7: 最重要タスク | E7: 前回の日報で決めたTop3のうち、売上に最も効く1つを最初に片付ける | F7: 午前中 | G7: 急ぎではないが重要な仕事は、後回しにするといつまでも終わらない。売上を動かす仕事を1日の最初に固定する
A8: 4 | B8: 売上 | C8: 新規アプローチを目標件数やる | D8: 新規アプローチ | E8: 架電・DM・訪問・紹介依頼などで、見込み客との新しい接点をつくる | F8: 本日の日報の目標件数 | G8: 受注は商談から、商談は接点から生まれる。入口の件数が足りなければ、成約率が高くても売上は伸びない
A9: 5 | B9: 売上 | C9: 既存顧客と話す | D9: 既存顧客 | E9: 最低1社と話し、課題・不満・追加の要望を聞く。満足している顧客には紹介を頼む | F9: 1社以上 | G9: 既存顧客からの追加受注と紹介は、新規開拓より獲得コストが低い。解約の兆しにも早く気づける
A10: 6 | B10: 売上 | C10: 商談を前に進める | D10: 商談前進 | E10: 案件パイプラインを更新し、すべての案件に次のアクションと期日を入れる。問い合わせや依頼には24時間以内に返す | F10: 全案件 | G10: 次の一手が決まっていない案件は失注しやすい。止まっている案件をゼロにする
A11: 7 | B11: 仕組み | C11: 仕事を1つ仕組み化する | D11: 仕組み化 | E11: 今日やった仕事から1つ選び、マニュアル・テンプレート・チェックリストにして共有する | F11: 1つ | G11: 年1000億は自分1人では届かない。誰がやっても同じ成果が出る手順があれば、新しく入った人が早く戦力になる
A12: 8 | B12: 仕組み | C12: 仕事を1つ手放す | D12: 手放す | E12: 自分がやらなくてよい仕事を1つ、人に任せる・自動化する・やめる | F12: 1つ | G12: 社長の時間は増やせない。手放して空いた時間を、売上・採用・提携に使う
A13: 9 | B13: 組織 | C13: 採用の接点を1つつくる | D13: 採用 | E13: 候補者と話す、スカウトを送る、知人に紹介を頼む、採用ページを直す、のいずれかをやる | F13: 1件 | G13: 1人あたり売上が1億円でも、年1000億には1,000人が必要になる。採用は毎日進めないと間に合わない
A14: 10 | B14: 組織 | C14: メンバー1人と向き合う | D14: メンバー | E14: 1on1・承認・感謝・フィードバックのいずれかを1人に行う | F14: 1人 | G14: 採用しても定着しなければ組織は大きくならない。育成と定着が採用の成果を決める
A15: 11 | B15: 商品 | C15: 顧客の声から改善を1つ実行する | D15: 改善 | E15: 商品・サービス・業務のどこかを、顧客の声をもとに1つ直す | F15: 1つ | G15: 毎日1つの改善は1年で約365個になる。競合との差は日々の改善の積み重ねでつく
A16: 12 | B16: 発信 | C16: 1つ発信する | D16: 発信 | E16: SNS・ブログ・導入事例・採用広報などで1つ発信する | F16: 1本 | G16: 発信は問い合わせ・採用応募・提携の相談を生む。知られていない会社には相談が来ない
... A20: 16 | B20: 振り返り | C20: 日報を書いて提出する | D20: 日報提出 | E20: 今日の結果を記録し、KPT（続けること・課題・次に試すこと）と明日のTop3を書いて提出する | F20: 夜15分 | G20: 何が効いたかを毎日記録すると、成果が出たやり方を再現できる。記録がなければ振り返りは記憶頼みになる
A22: 週に1回・月に1回やること（日報の振り返りを計画に戻す）
B23: 頻度 | C23: やること
A24: 1 | B24: 毎週 | C24: 月次集計で日課の実行率を見て、続かない日課の原因を1つ決めて手を打つ
A25: 2 | B25: 毎週 | C25: 案件パイプラインを全件見直し、止まっている案件の次の一手を決める
A26: 3 | B26: 毎週 | C26: 翌週の最重要テーマと売上目標を決める
A27: 4 | B27: 毎月 | C27: 月次集計で売上・粗利・営業利益を目標と比べ、差の原因を書き出す
A28: 5 | B28: 毎月 | C28: 設定シートの平均受注単価・受注率・商談化率を実績に合わせて更新する
A29: 6 | B29: 毎月 | C29: 採用・組織の計画を、10年計画の必要な営業担当者数と比べて見直す

Sheet 経費ログ
A1: 経費ログ（費用を1件1行で入力）
A2: 日付 | B2: 勘定科目 | C2: 内容・支払先 | D2: 金額（円・税込） | E2: 支払方法 | F2: 領収書 | G2: メモ | I2: 日付・勘定科目・金額は必須。科目が「原価：」で始まる費用は売上原価、それ以外は販管費になる。本日の日報の売上原価・販管費と、月次集計に自動で反映される。「記入例」の行は集計されない。
A3: 記入例 | B3: 販管費：旅費交通費 | C3: A社訪問（電車往復） | D3: 1280 | E3: 電子マネー・QR | F3: ○

Sheet 案件パイプライン
A1: 案件パイプライン（案件ごとに1行。フェーズと次のアクションを毎日更新）
A2: 登録日 | B2: 顧客名 | C2: 案件名・内容 | D2: フェーズ | E2: 見込金額（円） | F2: 受注予定日 | G2: 次のアクション | H2: 期日 | I2: 担当 | J2: 流入経路 | K2: メモ | M2: フェーズ別の集計
A3: 記入例 | B3: 株式会社サンプル | C3: 業務システム導入 | D3: 提案済 | E3: 1500000 | F3: 46356 | G3: 見積を再提出する | H3: 46300 | I3: 自分 | J3: 既存顧客の紹介 | M3: フェーズ | N3: 件数 | O3: 見込金額 | P3: 確度 | Q3: 加重金額
M4: ='設定'!K5&"" | N4: =COUNTIFS($A:$A,">0",$D:$D,M4) | O4: =SUMIFS($E:$E,$A:$A,">0",$D:$D,M4) | P4: ='設定'!L5 | Q4: =O4*P4
M5: ='設定'!K6&"" | N5: =COUNTIFS($A:$A,">0",$D:$D,M5) | O5: =SUMIFS($E:$E,$A:$A,">0",$D:$D,M5) | P5: ='設定'!L6 | Q5: =O5*P5
M6: ='設定'!K7&"" | N6: =COUNTIFS($A:$A,">0",$D:$D,M6) | O6: =SUMIFS($E:$E,$A:$A,">0",$D:$D,M6) | P6: ='設定'!L7 | Q6: =O6*P6
M7: ='設定'!K8&"" | N7: =COUNTIFS($A:$A,">0",$D:$D,M7) | O7: =SUMIFS($E:$E,$A:$A,">0",$D:$D,M7) | P7: ='設定'!L8 | Q7: =O7*P7
M8: ='設定'!K9&"" | N8: =COUNTIFS($A:$A,">0",$D:$D,M8) | O8: =SUMIFS($E:$E,$A:$A,">0",$D:$D,M8) | P8: ='設定'!L9 | Q8: =O8*P8
M9: ='設定'!K10&"" | N9: =COUNTIFS($A:$A,">0",$D:$D,M9) | O9: =SUMIFS($E:$E,$A:$A,">0",$D:$D,M9) | P9: ='設定'!L10 | Q9: =O9*P9
M10: ='設定'!K11&"" | N10: =COUNTIFS($A:$A,">0",$D:$D,M10) | O10: =SUMIFS($E:$E,$A:$A,">0",$D:$D,M10) | P10: ='設定'!L11 | Q10: =O10*P10
M11: ='設定'!K12&"" | N11: =COUNTIFS($A:$A,">0",$D:$D,M11) | O11: =SUMIFS($E:$E,$A:$A,">0",$D:$D,M11) | P11: ='設定'!L12 | Q11: =O11*P11
M12: 合計 | N12: =SUM(N4:N11) | O12: =SUM(O4:O11) | Q12: =SUM(Q4:Q11)
M14: 期日を過ぎた案件 | N14: =COUNTIFS($A:$A,">0",$H:$H,"<"&TODAY(),$D:$D,"<>"&'設定'!$K$10,$D:$D,"<>"&'設定'!$K$11) | O14: 受注・失注以外で、期日が今日より前の案件数
M16: 加重金額＝見込金額×確度（確度は設定シート）。「記入例」の行は集計されない。

Sheet 月次集計
A1: 月次集計（日次ログ・経費ログから自動集計）
A2: 表示する計画年目を変えると、その年の12か月を表示する。売上・営業実績は日次ログ、原価・販管費は経費ログから集計。
A4: 表示する計画年目 | B4: 1
A5: 期間 | B5: =EDATE('設定'!$B$5,12*($B$4-1)) | C5: 〜 | D5: =EDATE('設定'!$B$5,12*$B$4)-1
A7: 月 | B7: 売上高 | C7: 売上目標 | D7: 達成率 | E7: 売上原価 | F7: 粗利 | G7: 粗利率 | H7: 販管費 | I7: 営業利益 | J7: 営業利益率 | K7: 新規アプローチ | L7: 商談数 | M7: 受注数 | N7: 受注金額 | O7: 商談化率 | P7: 受注率 | Q7: 平均受注単価 | R7: 日報提出日数 | S7: 日課達成率（平均）
A8: =DATE(YEAR($B$5),MONTH($B$5),1) | B8: =SUMIFS('日次ログ'!$J:$J,'日次ログ'!$A:$A,">="&$A8,'日次ログ'!$A:$A,"<="&EOMONTH($A8,0)) | C8: =INDEX('10年計画'!$D$10:$D$19,$B$4)*10^8/12 | D8: =IF(C8=0,0,B8/C8) | E8: =SUMIFS('経費ログ'!$D:$D,'経費ログ'!$A:$A,">="&$A8,'経費ログ'!$A:$A,"<="&EOMONTH($A8,0),'経費ログ'!$B:$B,"原価：*") | F8: =B8-E8 | G8: =IF(B8=0,0,F8/B8) | H8: =SUMIFS('経費ログ'!$D:$D,'経費ログ'!$A:$A,">="&$A8,'経費ログ'!$A:$A,"<="&EOMONTH($A8,0))-E8 | I8: =F8-H8 | J8: =IF(B8=0,0,I8/B8) | K8: =SUMIFS('日次ログ'!$R:$R,'日次ログ'!$A:$A,">="&$A8,'日次ログ'!$A:$A,"<="&EOMONTH($A8,0)) | L8: =SUMIFS('日次ログ'!$T:$T,'日次ログ'!$A:$A,">="&$A8,'日次ログ'!$A:$A,"<="&EOMONTH($A8,0)) | M8: =SUMIFS('日次ログ'!$V:$V,'日次ログ'!$A:$A,">="&$A8,'日次ログ'!$A:$A,"<="&EOMONTH($A8,0)) | N8: =SUMIFS('日次ログ'!$W:$W,'日次ログ'!$A:$A,">="&$A8,'日次ログ'!$A:$A,"<="&EOMONTH($A8,0)) | O8: =IF(K8=0,0,L8/K8) | P8: =IF(L8=0,0,M8/L8) | Q8: =IF(M8=0,0,N8/M8) | R8: =COUNTIFS('日次ログ'!$A:$A,">="&$A8,'日次ログ'!$A:$A,"<="&EOMONTH($A8,0)) | S8: =IF(R8=0,0,SUMIFS('日次ログ'!$AP:$AP,'日次ログ'!$A:$A,">="&$A8,'日次ログ'!$A:$A,"<="&EOMONTH($A8,0))/R8)
A9: =EDATE(A8,1) | B9: =SUMIFS('日次ログ'!$J:$J,'日次ログ'!$A:$A,">="&$A9,'日次ログ'!$A:$A,"<="&EOMONTH($A9,0)) | C9: =INDEX('10年計画'!$D$10:$D$19,$B$4)*10^8/12 | D9: =IF(C9=0,0,B9/C9) | E9: =SUMIFS('経費ログ'!$D:$D,'経費ログ'!$A:$A,">="&$A9,'経費ログ'!$A:$A,"<="&EOMONTH($A9,0),'経費ログ'!$B:$B,"原価：*") | F9: =B9-E9 | G9: =IF(B9=0,0,F9/B9) | H9: =SUMIFS('経費ログ'!$D:$D,'経費ログ'!$A:$A,">="&$A9,'経費ログ'!$A:$A,"<="&EOMONTH($A9,0))-E9 | I9: =F9-H9 | J9: =IF(B9=0,0,I9/B9) | K9: =SUMIFS('日次ログ'!$R:$R,'日次ログ'!$A:$A,">="&$A9,'日次ログ'!$A:$A,"<="&EOMONTH($A9,0)) | L9: =SUMIFS('日次ログ'!$T:$T,'日次ログ'!$A:$A,">="&$A9,'日次ログ'!$A:$A,"<="&EOMONTH($A9,0)) | M9: =SUMIFS('日次ログ'!$V:$V,'日次ログ'!$A:$A,">="&$A9,'日次ログ'!$A:$A,"<="&EOMONTH($A9,0)) | N9: =SUMIFS('日次ログ'!$W:$W,'日次ログ'!$A:$A,">="&$A9,'日次ログ'!$A:$A,"<="&EOMONTH($A9,0)) | O9: =IF(K9=0,0,L9/K9) | P9: =IF(L9=0,0,M9/L9) | Q9: =IF(M9=0,0,N9/M9) | R9: =COUNTIFS('日次ログ'!$A:$A,">="&$A9,'日次ログ'!$A:$A,"<="&EOMONTH($A9,0)) | S9: =IF(R9=0,0,SUMIFS('日次ログ'!$AP:$AP,'日次ログ'!$A:$A,">="&$A9,'日次ログ'!$A:$A,"<="&EOMONTH($A9,0))/R9)
A10: =EDATE(A9,1) | B10: =SUMIFS('日次ログ'!$J:$J,'日次ログ'!$A:$A,">="&$A10,'日次ログ'!$A:$A,"<="&EOMONTH($A10,0)) | C10: =INDEX('10年計画'!$D$10:$D$19,$B$4)*10^8/12 | D10: =IF(C10=0,0,B10/C10) | E10: =SUMIFS('経費ログ'!$D:$D,'経費ログ'!$A:$A,">="&$A10,'経費ログ'!$A:$A,"<="&EOMONTH($A10,0),'経費ログ'!$B:$B,"原価：*") | F10: =B10-E10 | G10: =IF(B10=0,0,F10/B10) | H10: =SUMIFS('経費ログ'!$D:$D,'経費ログ'!$A:$A,">="&$A10,'経費ログ'!$A:$A,"<="&EOMONTH($A10,0))-E10 | I10: =F10-H10 | J10: =IF(B10=0,0,I10/B10) | K10: =SUMIFS('日次ログ'!$R:$R,'日次ログ'!$A:$A,">="&$A10,'日次ログ'!$A:$A,"<="&EOMONTH($A10,0)) | L10: =SUMIFS('日次ログ'!$T:$T,'日次ログ'!$A:$A,">="&$A10,'日次ログ'!$A:$A,"<="&EOMONTH($A10,0)) | M10: =SUMIFS('日次ログ'!$V:$V,'日次ログ'!$A:$A,">="&$A10,'日次ログ'!$A:$A,"<="&EOMONTH($A10,0)) | N10: =SUMIFS('日次ログ'!$W:$W,'日次ログ'!$A:$A,">="&$A10,'日次ログ'!$A:$A,"<="&EOMONTH($A10,0)) | O10: =IF(K10=0,0,L10/K10) | P10: =IF(L10=0,0,M10/L10) | Q10: =IF(M10=0,0,N10/M10) | R10: =COUNTIFS('日次ログ'!$A:$A,">="&$A10,'日次ログ'!$A:$A,"<="&EOMONTH($A10,0)) | S10: =IF(R10=0,0,SUMIFS('日次ログ'!$AP:$AP,'日次ログ'!$A:$A,">="&$A10,'日次ログ'!$A:$A,"<="&EOMONTH($A10,0))/R10)
A11: =EDATE(A10,1) | B11: =SUMIFS('日次ログ'!$J:$J,'日次ログ'!$A:$A,">="&$A11,'日次ログ'!$A:$A,"<="&EOMONTH($A11,0)) | C11: =INDEX('10年計画'!$D$10:$D$19,$B$4)*10^8/12 | D11: =IF(C11=0,0,B11/C11) | E11: =SUMIFS('経費ログ'!$D:$D,'経費ログ'!$A:$A,">="&$A11,'経費ログ'!$A:$A,"<="&EOMONTH($A11,0),'経費ログ'!$B:$B,"原価：*") | F11: =B11-E11 | G11: =IF(B11=0,0,F11/B11) | H11: =SUMIFS('経費ログ'!$D:$D,'経費ログ'!$A:$A,">="&$A11,'経費ログ'!$A:$A,"<="&EOMONTH($A11,0))-E11 | I11: =F11-H11 | J11: =IF(B11=0,0,I11/B11) | K11: =SUMIFS('日次ログ'!$R:$R,'日次ログ'!$A:$A,">="&$A11,'日次ログ'!$A:$A,"<="&EOMONTH($A11,0)) | L11: =SUMIFS('日次ログ'!$T:$T,'日次ログ'!$A:$A,">="&$A11,'日次ログ'!$A:$A,"<="&EOMONTH($A11,0)) | M11: =SUMIFS('日次ログ'!$V:$V,'日次ログ'!$A:$A,">="&$A11,'日次ログ'!$A:$A,"<="&EOMONTH($A11,0)) | N11: =SUMIFS('日次ログ'!$W:$W,'日次ログ'!$A:$A,">="&$A11,'日次ログ'!$A:$A,"<="&EOMONTH($A11,0)) | O11: =IF(K11=0,0,L11/K11) | P11: =IF(L11=0,0,M11/L11) | Q11: =IF(M11=0,0,N11/M11) | R11: =COUNTIFS('日次ログ'!$A:$A,">="&$A11,'日次ログ'!$A:$A,"<="&EOMONTH($A11,0)) | S11: =IF(R11=0,0,SUMIFS('日次ログ'!$AP:$AP,'日次ログ'!$A:$A,">="&$A11,'日次ログ'!$A:$A,"<="&EOMONTH($A11,0))/R11)
A12: =EDATE(A11,1) | B12: =SUMIFS('日次ログ'!$J:$J,'日次ログ'!$A:$A,">="&$A12,'日次ログ'!$A:$A,"<="&EOMONTH($A12,0)) | C12: =INDEX('10年計画'!$D$10:$D$19,$B$4)*10^8/12 | D12: =IF(C12=0,0,B12/C12) | E12: =SUMIFS('経費ログ'!$D:$D,'経費ログ'!$A:$A,">="&$A12,'経費ログ'!$A:$A,"<="&EOMONTH($A12,0),'経費ログ'!$B:$B,"原価：*") | F12: =B12-E12 | G12: =IF(B12=0,0,F12/B12) | H12: =SUMIFS('経費ログ'!$D:$D,'経費ログ'!$A:$A,">="&$A12,'経費ログ'!$A:$A,"<="&EOMONTH($A12,0))-E12 | I12: =F12-H12 | J12: =IF(B12=0,0,I12/B12) | K12: =SUMIFS('日次ログ'!$R:$R,'日次ログ'!$A:$A,">="&$A12,'日次ログ'!$A:$A,"<="&EOMONTH($A12,0)) | L12: =SUMIFS('日次ログ'!$T:$T,'日次ログ'!$A:$A,">="&$A12,'日次ログ'!$A:$A,"<="&EOMONTH($A12,0)) | M12: =SUMIFS('日次ログ'!$V:$V,'日次ログ'!$A:$A,">="&$A12,'日次ログ'!$A:$A,"<="&EOMONTH($A12,0)) | N12: =SUMIFS('日次ログ'!$W:$W,'日次ログ'!$A:$A,">="&$A12,'日次ログ'!$A:$A,"<="&EOMONTH($A12,0)) | O12: =IF(K12=0,0,L12/K12) | P12: =IF(L12=0,0,M12/L12) | Q12: =IF(M12=0,0,N12/M12) | R12: =COUNTIFS('日次ログ'!$A:$A,">="&$A12,'日次ログ'!$A:$A,"<="&EOMONTH($A12,0)) | S12: =IF(R12=0,0,SUMIFS('日次ログ'!$AP:$AP,'日次ログ'!$A:$A,">="&$A12,'日次ログ'!$A:$A,"<="&EOMONTH($A12,0))/R12)
A13: =EDATE(A12,1) | B13: =SUMIFS('日次ログ'!$J:$J,'日次ログ'!$A:$A,">="&$A13,'日次ログ'!$A:$A,"<="&EOMONTH($A13,0)) | C13: =INDEX('10年計画'!$D$10:$D$19,$B$4)*10^8/12 | D13: =IF(C13=0,0,B13/C13) | E13: =SUMIFS('経費ログ'!$D:$D,'経費ログ'!$A:$A,">="&$A13,'経費ログ'!$A:$A,"<="&EOMONTH($A13,0),'経費ログ'!$B:$B,"原価：*") | F13: =B13-E13 | G13: =IF(B13=0,0,F13/B13) | H13: =SUMIFS('経費ログ'!$D:$D,'経費ログ'!$A:$A,">="&$A13,'経費ログ'!$A:$A,"<="&EOMONTH($A13,0))-E13 | I13: =F13-H13 | J13: =IF(B13=0,0,I13/B13) | K13: =SUMIFS('日次ログ'!$R:$R,'日次ログ'!$A:$A,">="&$A13,'日次ログ'!$A:$A,"<="&EOMONTH($A13,0)) | L13: =SUMIFS('日次ログ'!$T:$T,'日次ログ'!$A:$A,">="&$A13,'日次ログ'!$A:$A,"<="&EOMONTH($A13,0)) | M13: =SUMIFS('日次ログ'!$V:$V,'日次ログ'!$A:$A,">="&$A13,'日次ログ'!$A:$A,"<="&EOMONTH($A13,0)) | N13: =SUMIFS('日次ログ'!$W:$W,'日次ログ'!$A:$A,">="&$A13,'日次ログ'!$A:$A,"<="&EOMONTH($A13,0)) | O13: =IF(K13=0,0,L13/K13) | P13: =IF(L13=0,0,M13/L13) | Q13: =IF(M13=0,0,N13/M13) | R13: =COUNTIFS('日次ログ'!$A:$A,">="&$A13,'日次ログ'!$A:$A,"<="&EOMONTH($A13,0)) | S13: =IF(R13=0,0,SUMIFS('日次ログ'!$AP:$AP,'日次ログ'!$A:$A,">="&$A13,'日次ログ'!$A:$A,"<="&EOMONTH($A13,0))/R13)
A14: =EDATE(A13,1) | B14: =SUMIFS('日次ログ'!$J:$J,'日次ログ'!$A:$A,">="&$A14,'日次ログ'!$A:$A,"<="&EOMONTH($A14,0)) | C14: =INDEX('10年計画'!$D$10:$D$19,$B$4)*10^8/12 | D14: =IF(C14=0,0,B14/C14) | E14: =SUMIFS('経費ログ'!$D:$D,'経費ログ'!$A:$A,">="&$A14,'経費ログ'!$A:$A,"<="&EOMONTH($A14,0),'経費ログ'!$B:$B,"原価：*") | F14: =B14-E14 | G14: =IF(B14=0,0,F14/B14) | H14: =SUMIFS('経費ログ'!$D:$D,'経費ログ'!$A:$A,">="&$A14,'経費ログ'!$A:$A,"<="&EOMONTH($A14,0))-E14 | I14: =F14-H14 | J14: =IF(B14=0,0,I14/B14) | K14: =SUMIFS('日次ログ'!$R:$R,'日次ログ'!$A:$A,">="&$A14,'日次ログ'!$A:$A,"<="&EOMONTH($A14,0)) | L14: =SUMIFS('日次ログ'!$T:$T,'日次ログ'!$A:$A,">="&$A14,'日次ログ'!$A:$A,"<="&EOMONTH($A14,0)) | M14: =SUMIFS('日次ログ'!$V:$V,'日次ログ'!$A:$A,">="&$A14,'日次ログ'!$A:$A,"<="&EOMONTH($A14,0)) | N14: =SUMIFS('日次ログ'!$W:$W,'日次ログ'!$A:$A,">="&$A14,'日次ログ'!$A:$A,"<="&EOMONTH($A14,0)) | O14: =IF(K14=0,0,L14/K14) | P14: =IF(L14=0,0,M14/L14) | Q14: =IF(M14=0,0,N14/M14) | R14: =COUNTIFS('日次ログ'!$A:$A,">="&$A14,'日次ログ'!$A:$A,"<="&EOMONTH($A14,0)) | S14: =IF(R14=0,0,SUMIFS('日次ログ'!$AP:$AP,'日次ログ'!$A:$A,">="&$A14,'日次ログ'!$A:$A,"<="&EOMONTH($A14,0))/R14)
A15: =EDATE(A14,1) | B15: =SUMIFS('日次ログ'!$J:$J,'日次ログ'!$A:$A,">="&$A15,'日次ログ'!$A:$A,"<="&EOMONTH($A15,0)) | C15: =INDEX('10年計画'!$D$10:$D$19,$B$4)*10^8/12 | D15: =IF(C15=0,0,B15/C15) | E15: =SUMIFS('経費ログ'!$D:$D,'経費ログ'!$A:$A,">="&$A15,'経費ログ'!$A:$A,"<="&EOMONTH($A15,0),'経費ログ'!$B:$B,"原価：*") | F15: =B15-E15 | G15: =IF(B15=0,0,F15/B15) | H15: =SUMIFS('経費ログ'!$D:$D,'経費ログ'!$A:$A,">="&$A15,'経費ログ'!$A:$A,"<="&EOMONTH($A15,0))-E15 | I15: =F15-H15 | J15: =IF(B15=0,0,I15/B15) | K15: =SUMIFS('日次ログ'!$R:$R,'日次ログ'!$A:$A,">="&$A15,'日次ログ'!$A:$A,"<="&EOMONTH($A15,0)) | L15: =SUMIFS('日次ログ'!$T:$T,'日次ログ'!$A:$A,">="&$A15,'日次ログ'!$A:$A,"<="&EOMONTH($A15,0)) | M15: =SUMIFS('日次ログ'!$V:$V,'日次ログ'!$A:$A,">="&$A15,'日次ログ'!$A:$A,"<="&EOMONTH($A15,0)) | N15: =SUMIFS('日次ログ'!$W:$W,'日次ログ'!$A:$A,">="&$A15,'日次ログ'!$A:$A,"<="&EOMONTH($A15,0)) | O15: =IF(K15=0,0,L15/K15) | P15: =IF(L15=0,0,M15/L15) | Q15: =IF(M15=0,0,N15/M15) | R15: =COUNTIFS('日次ログ'!$A:$A,">="&$A15,'日次ログ'!$A:$A,"<="&EOMONTH($A15,0)) | S15: =IF(R15=0,0,SUMIFS('日次ログ'!$AP:$AP,'日次ログ'!$A:$A,">="&$A15,'日次ログ'!$A:$A,"<="&EOMONTH($A15,0))/R15)
A16: =EDATE(A15,1) | B16: =SUMIFS('日次ログ'!$J:$J,'日次ログ'!$A:$A,">="&$A16,'日次ログ'!$A:$A,"<="&EOMONTH($A16,0)) | C16: =INDEX('10年計画'!$D$10:$D$19,$B$4)*10^8/12 | D16: =IF(C16=0,0,B16/C16) | E16: =SUMIFS('経費ログ'!$D:$D,'経費ログ'!$A:$A,">="&$A16,'経費ログ'!$A:$A,"<="&EOMONTH($A16,0),'経費ログ'!$B:$B,"原価：*") | F16: =B16-E16 | G16: =IF(B16=0,0,F16/B16) | H16: =SUMIFS('経費ログ'!$D:$D,'経費ログ'!$A:$A,">="&$A16,'経費ログ'!$A:$A,"<="&EOMONTH($A16,0))-E16 | I16: =F16-H16 | J16: =IF(B16=0,0,I16/B16) | K16: =SUMIFS('日次ログ'!$R:$R,'日次ログ'!$A:$A,">="&$A16,'日次ログ'!$A:$A,"<="&EOMONTH($A16,0)) | L16: =SUMIFS('日次ログ'!$T:$T,'日次ログ'!$A:$A,">="&$A16,'日次ログ'!$A:$A,"<="&EOMONTH($A16,0)) | M16: =SUMIFS('日次ログ'!$V:$V,'日次ログ'!$A:$A,">="&$A16,'日次ログ'!$A:$A,"<="&EOMONTH($A16,0)) | N16: =SUMIFS('日次ログ'!$W:$W,'日次ログ'!$A:$A,">="&$A16,'日次ログ'!$A:$A,"<="&EOMONTH($A16,0)) | O16: =IF(K16=0,0,L16/K16) | P16: =IF(L16=0,0,M16/L16) | Q16: =IF(M16=0,0,N16/M16) | R16: =COUNTIFS('日次ログ'!$A:$A,">="&$A16,'日次ログ'!$A:$A,"<="&EOMONTH($A16,0)) | S16: =IF(R16=0,0,SUMIFS('日次ログ'!$AP:$AP,'日次ログ'!$A:$A,">="&$A16,'日次ログ'!$A:$A,"<="&EOMONTH($A16,0))/R16)
A17: =EDATE(A16,1) | B17: =SUMIFS('日次ログ'!$J:$J,'日次ログ'!$A:$A,">="&$A17,'日次ログ'!$A:$A,"<="&EOMONTH($A17,0)) | C17: =INDEX('10年計画'!$D$10:$D$19,$B$4)*10^8/12 | D17: =IF(C17=0,0,B17/C17) | E17: =SUMIFS('経費ログ'!$D:$D,'経費ログ'!$A:$A,">="&$A17,'経費ログ'!$A:$A,"<="&EOMONTH($A17,0),'経費ログ'!$B:$B,"原価：*") | F17: =B17-E17 | G17: =IF(B17=0,0,F17/B17) | H17: =SUMIFS('経費ログ'!$D:$D,'経費ログ'!$A:$A,">="&$A17,'経費ログ'!$A:$A,"<="&EOMONTH($A17,0))-E17 | I17: =F17-H17 | J17: =IF(B17=0,0,I17/B17) | K17: =SUMIFS('日次ログ'!$R:$R,'日次ログ'!$A:$A,">="&$A17,'日次ログ'!$A:$A,"<="&EOMONTH($A17,0)) | L17: =SUMIFS('日次ログ'!$T:$T,'日次ログ'!$A:$A,">="&$A17,'日次ログ'!$A:$A,"<="&EOMONTH($A17,0)) | M17: =SUMIFS('日次ログ'!$V:$V,'日次ログ'!$A:$A,">="&$A17,'日次ログ'!$A:$A,"<="&EOMONTH($A17,0)) | N17: =SUMIFS('日次ログ'!$W:$W,'日次ログ'!$A:$A,">="&$A17,'日次ログ'!$A:$A,"<="&EOMONTH($A17,0)) | O17: =IF(K17=0,0,L17/K17) | P17: =IF(L17=0,0,M17/L17) | Q17: =IF(M17=0,0,N17/M17) | R17: =COUNTIFS('日次ログ'!$A:$A,">="&$A17,'日次ログ'!$A:$A,"<="&EOMONTH($A17,0)) | S17: =IF(R17=0,0,SUMIFS('日次ログ'!$AP:$AP,'日次ログ'!$A:$A,">="&$A17,'日次ログ'!$A:$A,"<="&EOMONTH($A17,0))/R17)
A18: =EDATE(A17,1) | B18: =SUMIFS('日次ログ'!$J:$J,'日次ログ'!$A:$A,">="&$A18,'日次ログ'!$A:$A,"<="&EOMONTH($A18,0)) | C18: =INDEX('10年計画'!$D$10:$D$19,$B$4)*10^8/12 | D18: =IF(C18=0,0,B18/C18) | E18: =SUMIFS('経費ログ'!$D:$D,'経費ログ'!$A:$A,">="&$A18,'経費ログ'!$A:$A,"<="&EOMONTH($A18,0),'経費ログ'!$B:$B,"原価：*") | F18: =B18-E18 | G18: =IF(B18=0,0,F18/B18) | H18: =SUMIFS('経費ログ'!$D:$D,'経費ログ'!$A:$A,">="&$A18,'経費ログ'!$A:$A,"<="&EOMONTH($A18,0))-E18 | I18: =F18-H18 | J18: =IF(B18=0,0,I18/B18) | K18: =SUMIFS('日次ログ'!$R:$R,'日次ログ'!$A:$A,">="&$A18,'日次ログ'!$A:$A,"<="&EOMONTH($A18,0)) | L18: =SUMIFS('日次ログ'!$T:$T,'日次ログ'!$A:$A,">="&$A18,'日次ログ'!$A:$A,"<="&EOMONTH($A18,0)) | M18: =SUMIFS('日次ログ'!$V:$V,'日次ログ'!$A:$A,">="&$A18,'日次ログ'!$A:$A,"<="&EOMONTH($A18,0)) | N18: =SUMIFS('日次ログ'!$W:$W,'日次ログ'!$A:$A,">="&$A18,'日次ログ'!$A:$A,"<="&EOMONTH($A18,0)) | O18: =IF(K18=0,0,L18/K18) | P18: =IF(L18=0,0,M18/L18) | Q18: =IF(M18=0,0,N18/M18) | R18: =COUNTIFS('日次ログ'!$A:$A,">="&$A18,'日次ログ'!$A:$A,"<="&EOMONTH($A18,0)) | S18: =IF(R18=0,0,SUMIFS('日次ログ'!$AP:$AP,'日次ログ'!$A:$A,">="&$A18,'日次ログ'!$A:$A,"<="&EOMONTH($A18,0))/R18)
A19: =EDATE(A18,1) | B19: =SUMIFS('日次ログ'!$J:$J,'日次ログ'!$A:$A,">="&$A19,'日次ログ'!$A:$A,"<="&EOMONTH($A19,0)) | C19: =INDEX('10年計画'!$D$10:$D$19,$B$4)*10^8/12 | D19: =IF(C19=0,0,B19/C19) | E19: =SUMIFS('経費ログ'!$D:$D,'経費ログ'!$A:$A,">="&$A19,'経費ログ'!$A:$A,"<="&EOMONTH($A19,0),'経費ログ'!$B:$B,"原価：*") | F19: =B19-E19 | G19: =IF(B19=0,0,F19/B19) | H19: =SUMIFS('経費ログ'!$D:$D,'経費ログ'!$A:$A,">="&$A19,'経費ログ'!$A:$A,"<="&EOMONTH($A19,0))-E19 | I19: =F19-H19 | J19: =IF(B19=0,0,I19/B19) | K19: =SUMIFS('日次ログ'!$R:$R,'日次ログ'!$A:$A,">="&$A19,'日次ログ'!$A:$A,"<="&EOMONTH($A19,0)) | L19: =SUMIFS('日次ログ'!$T:$T,'日次ログ'!$A:$A,">="&$A19,'日次ログ'!$A:$A,"<="&EOMONTH($A19,0)) | M19: =SUMIFS('日次ログ'!$V:$V,'日次ログ'!$A:$A,">="&$A19,'日次ログ'!$A:$A,"<="&EOMONTH($A19,0)) | N19: =SUMIFS('日次ログ'!$W:$W,'日次ログ'!$A:$A,">="&$A19,'日次ログ'!$A:$A,"<="&EOMONTH($A19,0)) | O19: =IF(K19=0,0,L19/K19) | P19: =IF(L19=0,0,M19/L19) | Q19: =IF(M19=0,0,N19/M19) | R19: =COUNTIFS('日次ログ'!$A:$A,">="&$A19,'日次ログ'!$A:$A,"<="&EOMONTH($A19,0)) | S19: =IF(R19=0,0,SUMIFS('日次ログ'!$AP:$AP,'日次ログ'!$A:$A,">="&$A19,'日次ログ'!$A:$A,"<="&EOMONTH($A19,0))/R19)
A20: 年間合計 | B20: =SUM(B8:B19) | C20: =SUM(C8:C19) | D20: =IF(C20=0,0,B20/C20) | E20: =SUM(E8:E19) | F20: =SUM(F8:F19) | G20: =IF(B20=0,0,F20/B20) | H20: =SUM(H8:H19) | I20: =SUM(I8:I19) | J20: =IF(B20=0,0,I20/B20) | K20: =SUM(K8:K19) | L20: =SUM(L8:L19) | M20: =SUM(M8:M19) | N20: =SUM(N8:N19) | O20: =IF(K20=0,0,L20/K20) | P20: =IF(L20=0,0,M20/L20) | Q20: =IF(M20=0,0,N20/M20) | R20: =SUM(R8:R19) | S20: =IF(R20=0,0,SUMPRODUCT(S8:S19,R8:R19)/R20)
A22: 日課の実行率（○をつけた日数÷日報を提出した日数）
A23: No | B23: 日課 | C23: =DATE(YEAR($B$5),MONTH($B$5),1) | D23: =EDATE(C23,1) | E23: =EDATE(D23,1) | F23: =EDATE(E23,1) | G23: =EDATE(F23,1) | H23: =EDATE(G23,1) | I23: =EDATE(H23,1) | J23: =EDATE(I23,1) | K23: =EDATE(J23,1) | ... N23: =EDATE(M23,1)
B24: 日報を提出した日数 | C24: =COUNTIFS('日次ログ'!$A:$A,">="&C$23,'日次ログ'!$A:$A,"<="&EOMONTH(C$23,0)) | D24: =COUNTIFS('日次ログ'!$A:$A,">="&D$23,'日次ログ'!$A:$A,"<="&EOMONTH(D$23,0)) | E24: =COUNTIFS('日次ログ'!$A:$A,">="&E$23,'日次ログ'!$A:$A,"<="&EOMONTH(E$23,0)) | F24: =COUNTIFS('日次ログ'!$A:$A,">="&F$23,'日次ログ'!$A:$A,"<="&EOMONTH(F$23,0)) | G24: =COUNTIFS('日次ログ'!$A:$A,">="&G$23,'日次ログ'!$A:$A,"<="&EOMONTH(G$23,0)) | H24: =COUNTIFS('日次ログ'!$A:$A,">="&H$23,'日次ログ'!$A:$A,"<="&EOMONTH(H$23,0)) | I24: =COUNTIFS('日次ログ'!$A:$A,">="&I$23,'日次ログ'!$A:$A,"<="&EOMONTH(I$23,0)) | J24: =COUNTIFS('日次ログ'!$A:$A,">="&J$23,'日次ログ'!$A:$A,"<="&EOMONTH(J$23,0)) | ... N24: =COUNTIFS('日次ログ'!$A:$A,">="&N$23,'日次ログ'!$A:$A,"<="&EOMONTH(N$23,0))
A25: 1 | B25: ='毎日やること'!C5&"" | C25: =IF(C$24=0,"",COUNTIFS('日次ログ'!$A:$A,">="&C$23,'日次ログ'!$A:$A,"<="&EOMONTH(C$23,0),INDEX('日次ログ'!$Z:$AO,0,$A25),"○")/C$24) | D25: =IF(D$24=0,"",COUNTIFS('日次ログ'!$A:$A,">="&D$23,'日次ログ'!$A:$A,"<="&EOMONTH(D$23,0),INDEX('日次ログ'!$Z:$AO,0,$A25),"○")/D$24) | E25: =IF(E$24=0,"",COUNTIFS('日次ログ'!$A:$A,">="&E$23,'日次ログ'!$A:$A,"<="&EOMONTH(E$23,0),INDEX('日次ログ'!$Z:$AO,0,$A25),"○")/E$24) | F25: =IF(F$24=0,"",COUNTIFS('日次ログ'!$A:$A,">="&F$23,'日次ログ'!$A:$A,"<="&EOMONTH(F$23,0),INDEX('日次ログ'!$Z:$AO,0,$A25),"○")/F$24) | G25: =IF(G$24=0,"",COUNTIFS('日次ログ'!$A:$A,">="&G$23,'日次ログ'!$A:$A,"<="&EOMONTH(G$23,0),INDEX('日次ログ'!$Z:$AO,0,$A25),"○")/G$24) | H25: =IF(H$24=0,"",COUNTIFS('日次ログ'!$A:$A,">="&H$23,'日次ログ'!$A:$A,"<="&EOMONTH(H$23,0),INDEX('日次ログ'!$Z:$AO,0,$A25),"○")/H$24) | I25: =IF(I$24=0,"",COUNTIFS('日次ログ'!$A:$A,">="&I$23,'日次ログ'!$A:$A,"<="&EOMONTH(I$23,0),INDEX('日次ログ'!$Z:$AO,0,$A25),"○")/I$24) | J25: =IF(J$24=0,"",COUNTIFS('日次ログ'!$A:$A,">="&J$23,'日次ログ'!$A:$A,"<="&EOMONTH(J$23,0),INDEX('日次ログ'!$Z:$AO,0,$A25),"○")/J$24) | ... N25: =IF(N$24=0,"",COUNTIFS('日次ログ'!$A:$A,">="&N$23,'日次ログ'!$A:$A,"<="&EOMONTH(N$23,0),INDEX('日次ログ'!$Z:$AO,0,$A25),"○")/N$24)
A26: 2 | B26: ='毎日やること'!C6&"" | C26: =IF(C$24=0,"",COUNTIFS('日次ログ'!$A:$A,">="&C$23,'日次ログ'!$A:$A,"<="&EOMONTH(C$23,0),INDEX('日次ログ'!$Z:$AO,0,$A26),"○")/C$24) | D26: =IF(D$24=0,"",COUNTIFS('日次ログ'!$A:$A,">="&D$23,'日次ログ'!$A:$A,"<="&EOMONTH(D$23,0),INDEX('日次ログ'!$Z:$AO,0,$A26),"○")/D$24) | E26: =IF(E$24=0,"",COUNTIFS('日次ログ'!$A:$A,">="&E$23,'日次ログ'!$A:$A,"<="&EOMONTH(E$23,0),INDEX('日次ログ'!$Z:$AO,0,$A26),"○")/E$24) | F26: =IF(F$24=0,"",COUNTIFS('日次ログ'!$A:$A,">="&F$23,'日次ログ'!$A:$A,"<="&EOMONTH(F$23,0),INDEX('日次ログ'!$Z:$AO,0,$A26),"○")/F$24) | G26: =IF(G$24=0,"",COUNTIFS('日次ログ'!$A:$A,">="&G$23,'日次ログ'!$A:$A,"<="&EOMONTH(G$23,0),INDEX('日次ログ'!$Z:$AO,0,$A26),"○")/G$24) | H26: =IF(H$24=0,"",COUNTIFS('日次ログ'!$A:$A,">="&H$23,'日次ログ'!$A:$A,"<="&EOMONTH(H$23,0),INDEX('日次ログ'!$Z:$AO,0,$A26),"○")/H$24) | I26: =IF(I$24=0,"",COUNTIFS('日次ログ'!$A:$A,">="&I$23,'日次ログ'!$A:$A,"<="&EOMONTH(I$23,0),INDEX('日次ログ'!$Z:$AO,0,$A26),"○")/I$24) | J26: =IF(J$24=0,"",COUNTIFS('日次ログ'!$A:$A,">="&J$23,'日次ログ'!$A:$A,"<="&EOMONTH(J$23,0),INDEX('日次ログ'!$Z:$AO,0,$A26),"○")/J$24) | ... N26: =IF(N$24=0,"",COUNTIFS('日次ログ'!$A:$A,">="&N$23,'日次ログ'!$A:$A,"<="&EOMONTH(N$23,0),INDEX('日次ログ'!$Z:$AO,0,$A26),"○")/N$24)
A27: 3 | B27: ='毎日やること'!C7&"" | C27: =IF(C$24=0,"",COUNTIFS('日次ログ'!$A:$A,">="&C$23,'日次ログ'!$A:$A,"<="&EOMONTH(C$23,0),INDEX('日次ログ'!$Z:$AO,0,$A27),"○")/C$24) | D27: =IF(D$24=0,"",COUNTIFS('日次ログ'!$A:$A,">="&D$23,'日次ログ'!$A:$A,"<="&EOMONTH(D$23,0),INDEX('日次ログ'!$Z:$AO,0,$A27),"○")/D$24) | E27: =IF(E$24=0,"",COUNTIFS('日次ログ'!$A:$A,">="&E$23,'日次ログ'!$A:$A,"<="&EOMONTH(E$23,0),INDEX('日次ログ'!$Z:$AO,0,$A27),"○")/E$24) | F27: =IF(F$24=0,"",COUNTIFS('日次ログ'!$A:$A,">="&F$23,'日次ログ'!$A:$A,"<="&EOMONTH(F$23,0),INDEX('日次ログ'!$Z:$AO,0,$A27),"○")/F$24) | G27: =IF(G$24=0,"",COUNTIFS('日次ログ'!$A:$A,">="&G$23,'日次ログ'!$A:$A,"<="&EOMONTH(G$23,0),INDEX('日次ログ'!$Z:$AO,0,$A27),"○")/G$24) | H27: =IF(H$24=0,"",COUNTIFS('日次ログ'!$A:$A,">="&H$23,'日次ログ'!$A:$A,"<="&EOMONTH(H$23,0),INDEX('日次ログ'!$Z:$AO,0,$A27),"○")/H$24) | I27: =IF(I$24=0,"",COUNTIFS('日次ログ'!$A:$A,">="&I$23,'日次ログ'!$A:$A,"<="&EOMONTH(I$23,0),INDEX('日次ログ'!$Z:$AO,0,$A27),"○")/I$24) | J27: =IF(J$24=0,"",COUNTIFS('日次ログ'!$A:$A,">="&J$23,'日次ログ'!$A:$A,"<="&EOMONTH(J$23,0),INDEX('日次ログ'!$Z:$AO,0,$A27),"○")/J$24) | ... N27: =IF(N$24=0,"",COUNTIFS('日次ログ'!$A:$A,">="&N$23,'日次ログ'!$A:$A,"<="&EOMONTH(N$23,0),INDEX('日次ログ'!$Z:$AO,0,$A27),"○")/N$24)
A28: 4 | B28: ='毎日やること'!C8&"" | C28: =IF(C$24=0,"",COUNTIFS('日次ログ'!$A:$A,">="&C$23,'日次ログ'!$A:$A,"<="&EOMONTH(C$23,0),INDEX('日次ログ'!$Z:$AO,0,$A28),"○")/C$24) | D28: =IF(D$24=0,"",COUNTIFS('日次ログ'!$A:$A,">="&D$23,'日次ログ'!$A:$A,"<="&EOMONTH(D$23,0),INDEX('日次ログ'!$Z:$AO,0,$A28),"○")/D$24) | E28: =IF(E$24=0,"",COUNTIFS('日次ログ'!$A:$A,">="&E$23,'日次ログ'!$A:$A,"<="&EOMONTH(E$23,0),INDEX('日次ログ'!$Z:$AO,0,$A28),"○")/E$24) | F28: =IF(F$24=0,"",COUNTIFS('日次ログ'!$A:$A,">="&F$23,'日次ログ'!$A:$A,"<="&EOMONTH(F$23,0),INDEX('日次ログ'!$Z:$AO,0,$A28),"○")/F$24) | G28: =IF(G$24=0,"",COUNTIFS('日次ログ'!$A:$A,">="&G$23,'日次ログ'!$A:$A,"<="&EOMONTH(G$23,0),INDEX('日次ログ'!$Z:$AO,0,$A28),"○")/G$24) | H28: =IF(H$24=0,"",COUNTIFS('日次ログ'!$A:$A,">="&H$23,'日次ログ'!$A:$A,"<="&EOMONTH(H$23,0),INDEX('日次ログ'!$Z:$AO,0,$A28),"○")/H$24) | I28: =IF(I$24=0,"",COUNTIFS('日次ログ'!$A:$A,">="&I$23,'日次ログ'!$A:$A,"<="&EOMONTH(I$23,0),INDEX('日次ログ'!$Z:$AO,0,$A28),"○")/I$24) | J28: =IF(J$24=0,"",COUNTIFS('日次ログ'!$A:$A,">="&J$23,'日次ログ'!$A:$A,"<="&EOMONTH(J$23,0),INDEX('日次ログ'!$Z:$AO,0,$A28),"○")/J$24) | ... N28: =IF(N$24=0,"",COUNTIFS('日次ログ'!$A:$A,">="&N$23,'日次ログ'!$A:$A,"<="&EOMONTH(N$23,0),INDEX('日次ログ'!$Z:$AO,0,$A28),"○")/N$24)
A29: 5 | B29: ='毎日やること'!C9&"" | C29: =IF(C$24=0,"",COUNTIFS('日次ログ'!$A:$A,">="&C$23,'日次ログ'!$A:$A,"<="&EOMONTH(C$23,0),INDEX('日次ログ'!$Z:$AO,0,$A29),"○")/C$24) | D29: =IF(D$24=0,"",COUNTIFS('日次ログ'!$A:$A,">="&D$23,'日次ログ'!$A:$A,"<="&EOMONTH(D$23,0),INDEX('日次ログ'!$Z:$AO,0,$A29),"○")/D$24) | E29: =IF(E$24=0,"",COUNTIFS('日次ログ'!$A:$A,">="&E$23,'日次ログ'!$A:$A,"<="&EOMONTH(E$23,0),INDEX('日次ログ'!$Z:$AO,0,$A29),"○")/E$24) | F29: =IF(F$24=0,"",COUNTIFS('日次ログ'!$A:$A,">="&F$23,'日次ログ'!$A:$A,"<="&EOMONTH(F$23,0),INDEX('日次ログ'!$Z:$AO,0,$A29),"○")/F$24) | G29: =IF(G$24=0,"",COUNTIFS('日次ログ'!$A:$A,">="&G$23,'日次ログ'!$A:$A,"<="&EOMONTH(G$23,0),INDEX('日次ログ'!$Z:$AO,0,$A29),"○")/G$24) | H29: =IF(H$24=0,"",COUNTIFS('日次ログ'!$A:$A,">="&H$23,'日次ログ'!$A:$A,"<="&EOMONTH(H$23,0),INDEX('日次ログ'!$Z:$AO,0,$A29),"○")/H$24) | I29: =IF(I$24=0,"",COUNTIFS('日次ログ'!$A:$A,">="&I$23,'日次ログ'!$A:$A,"<="&EOMONTH(I$23,0),INDEX('日次ログ'!$Z:$AO,0,$A29),"○")/I$24) | J29: =IF(J$24=0,"",COUNTIFS('日次ログ'!$A:$A,">="&J$23,'日次ログ'!$A:$A,"<="&EOMONTH(J$23,0),INDEX('日次ログ'!$Z:$AO,0,$A29),"○")/J$24) | ... N29: =IF(N$24=0,"",COUNTIFS('日次ログ'!$A:$A,">="&N$23,'日次ログ'!$A:$A,"<="&EOMONTH(N$23,0),INDEX('日次ログ'!$Z:$AO,0,$A29),"○")/N$24)
A30: 6 | B30: ='毎日やること'!C10&"" | C30: =IF(C$24=0,"",COUNTIFS('日次ログ'!$A:$A,">="&C$23,'日次ログ'!$A:$A,"<="&EOMONTH(C$23,0),INDEX('日次ログ'!$Z:$AO,0,$A30),"○")/C$24) | D30: =IF(D$24=0,"",COUNTIFS('日次ログ'!$A:$A,">="&D$23,'日次ログ'!$A:$A,"<="&EOMONTH(D$23,0),INDEX('日次ログ'!$Z:$AO,0,$A30),"○")/D$24) | E30: =IF(E$24=0,"",COUNTIFS('日次ログ'!$A:$A,">="&E$23,'日次ログ'!$A:$A,"<="&EOMONTH(E$23,0),INDEX('日次ログ'!$Z:$AO,0,$A30),"○")/E$24) | F30: =IF(F$24=0,"",COUNTIFS('日次ログ'!$A:$A,">="&F$23,'日次ログ'!$A:$A,"<="&EOMONTH(F$23,0),INDEX('日次ログ'!$Z:$AO,0,$A30),"○")/F$24) | G30: =IF(G$24=0,"",COUNTIFS('日次ログ'!$A:$A,">="&G$23,'日次ログ'!$A:$A,"<="&EOMONTH(G$23,0),INDEX('日次ログ'!$Z:$AO,0,$A30),"○")/G$24) | H30: =IF(H$24=0,"",COUNTIFS('日次ログ'!$A:$A,">="&H$23,'日次ログ'!$A:$A,"<="&EOMONTH(H$23,0),INDEX('日次ログ'!$Z:$AO,0,$A30),"○")/H$24) | I30: =IF(I$24=0,"",COUNTIFS('日次ログ'!$A:$A,">="&I$23,'日次ログ'!$A:$A,"<="&EOMONTH(I$23,0),INDEX('日次ログ'!$Z:$AO,0,$A30),"○")/I$24) | J30: =IF(J$24=0,"",COUNTIFS('日次ログ'!$A:$A,">="&J$23,'日次ログ'!$A:$A,"<="&EOMONTH(J$23,0),INDEX('日次ログ'!$Z:$AO,0,$A30),"○")/J$24) | ... N30: =IF(N$24=0,"",COUNTIFS('日次ログ'!$A:$A,">="&N$23,'日次ログ'!$A:$A,"<="&EOMONTH(N$23,0),INDEX('日次ログ'!$Z:$AO,0,$A30),"○")/N$24)
A31: 7 | B31: ='毎日やること'!C11&"" | C31: =IF(C$24=0,"",COUNTIFS('日次ログ'!$A:$A,">="&C$23,'日次ログ'!$A:$A,"<="&EOMONTH(C$23,0),INDEX('日次ログ'!$Z:$AO,0,$A31),"○")/C$24) | D31: =IF(D$24=0,"",COUNTIFS('日次ログ'!$A:$A,">="&D$23,'日次ログ'!$A:$A,"<="&EOMONTH(D$23,0),INDEX('日次ログ'!$Z:$AO,0,$A31),"○")/D$24) | E31: =IF(E$24=0,"",COUNTIFS('日次ログ'!$A:$A,">="&E$23,'日次ログ'!$A:$A,"<="&EOMONTH(E$23,0),INDEX('日次ログ'!$Z:$AO,0,$A31),"○")/E$24) | F31: =IF(F$24=0,"",COUNTIFS('日次ログ'!$A:$A,">="&F$23,'日次ログ'!$A:$A,"<="&EOMONTH(F$23,0),INDEX('日次ログ'!$Z:$AO,0,$A31),"○")/F$24) | G31: =IF(G$24=0,"",COUNTIFS('日次ログ'!$A:$A,">="&G$23,'日次ログ'!$A:$A,"<="&EOMONTH(G$23,0),INDEX('日次ログ'!$Z:$AO,0,$A31),"○")/G$24) | H31: =IF(H$24=0,"",COUNTIFS('日次ログ'!$A:$A,">="&H$23,'日次ログ'!$A:$A,"<="&EOMONTH(H$23,0),INDEX('日次ログ'!$Z:$AO,0,$A31),"○")/H$24) | I31: =IF(I$24=0,"",COUNTIFS('日次ログ'!$A:$A,">="&I$23,'日次ログ'!$A:$A,"<="&EOMONTH(I$23,0),INDEX('日次ログ'!$Z:$AO,0,$A31),"○")/I$24) | J31: =IF(J$24=0,"",COUNTIFS('日次ログ'!$A:$A,">="&J$23,'日次ログ'!$A:$A,"<="&EOMONTH(J$23,0),INDEX('日次ログ'!$Z:$AO,0,$A31),"○")/J$24) | ... N31: =IF(N$24=0,"",COUNTIFS('日次ログ'!$A:$A,">="&N$23,'日次ログ'!$A:$A,"<="&EOMONTH(N$23,0),INDEX('日次ログ'!$Z:$AO,0,$A31),"○")/N$24)
A32: 8 | B32: ='毎日やること'!C12&"" | C32: =IF(C$24=0,"",COUNTIFS('日次ログ'!$A:$A,">="&C$23,'日次ログ'!$A:$A,"<="&EOMONTH(C$23,0),INDEX('日次ログ'!$Z:$AO,0,$A32),"○")/C$24) | D32: =IF(D$24=0,"",COUNTIFS('日次ログ'!$A:$A,">="&D$23,'日次ログ'!$A:$A,"<="&EOMONTH(D$23,0),INDEX('日次ログ'!$Z:$AO,0,$A32),"○")/D$24) | E32: =IF(E$24=0,"",COUNTIFS('日次ログ'!$A:$A,">="&E$23,'日次ログ'!$A:$A,"<="&EOMONTH(E$23,0),INDEX('日次ログ'!$Z:$AO,0,$A32),"○")/E$24) | F32: =IF(F$24=0,"",COUNTIFS('日次ログ'!$A:$A,">="&F$23,'日次ログ'!$A:$A,"<="&EOMONTH(F$23,0),INDEX('日次ログ'!$Z:$AO,0,$A32),"○")/F$24) | G32: =IF(G$24=0,"",COUNTIFS('日次ログ'!$A:$A,">="&G$23,'日次ログ'!$A:$A,"<="&EOMONTH(G$23,0),INDEX('日次ログ'!$Z:$AO,0,$A32),"○")/G$24) | H32: =IF(H$24=0,"",COUNTIFS('日次ログ'!$A:$A,">="&H$23,'日次ログ'!$A:$A,"<="&EOMONTH(H$23,0),INDEX('日次ログ'!$Z:$AO,0,$A32),"○")/H$24) | I32: =IF(I$24=0,"",COUNTIFS('日次ログ'!$A:$A,">="&I$23,'日次ログ'!$A:$A,"<="&EOMONTH(I$23,0),INDEX('日次ログ'!$Z:$AO,0,$A32),"○")/I$24) | J32: =IF(J$24=0,"",COUNTIFS('日次ログ'!$A:$A,">="&J$23,'日次ログ'!$A:$A,"<="&EOMONTH(J$23,0),INDEX('日次ログ'!$Z:$AO,0,$A32),"○")/J$24) | ... N32: =IF(N$24=0,"",COUNTIFS('日次ログ'!$A:$A,">="&N$23,'日次ログ'!$A:$A,"<="&EOMONTH(N$23,0),INDEX('日次ログ'!$Z:$AO,0,$A32),"○")/N$24)
A33: 9 | B33: ='毎日やること'!C13&"" | C33: =IF(C$24=0,"",COUNTIFS('日次ログ'!$A:$A,">="&C$23,'日次ログ'!$A:$A,"<="&EOMONTH(C$23,0),INDEX('日次ログ'!$Z:$AO,0,$A33),"○")/C$24) | D33: =IF(D$24=0,"",COUNTIFS('日次ログ'!$A:$A,">="&D$23,'日次ログ'!$A:$A,"<="&EOMONTH(D$23,0),INDEX('日次ログ'!$Z:$AO,0,$A33),"○")/D$24) | E33: =IF(E$24=0,"",COUNTIFS('日次ログ'!$A:$A,">="&E$23,'日次ログ'!$A:$A,"<="&EOMONTH(E$23,0),INDEX('日次ログ'!$Z:$AO,0,$A33),"○")/E$24) | F33: =IF(F$24=0,"",COUNTIFS('日次ログ'!$A:$A,">="&F$23,'日次ログ'!$A:$A,"<="&EOMONTH(F$23,0),INDEX('日次ログ'!$Z:$AO,0,$A33),"○")/F$24) | G33: =IF(G$24=0,"",COUNTIFS('日次ログ'!$A:$A,">="&G$23,'日次ログ'!$A:$A,"<="&EOMONTH(G$23,0),INDEX('日次ログ'!$Z:$AO,0,$A33),"○")/G$24) | H33: =IF(H$24=0,"",COUNTIFS('日次ログ'!$A:$A,">="&H$23,'日次ログ'!$A:$A,"<="&EOMONTH(H$23,0),INDEX('日次ログ'!$Z:$AO,0,$A33),"○")/H$24) | I33: =IF(I$24=0,"",COUNTIFS('日次ログ'!$A:$A,">="&I$23,'日次ログ'!$A:$A,"<="&EOMONTH(I$23,0),INDEX('日次ログ'!$Z:$AO,0,$A33),"○")/I$24) | J33: =IF(J$24=0,"",COUNTIFS('日次ログ'!$A:$A,">="&J$23,'日次ログ'!$A:$A,"<="&EOMONTH(J$23,0),INDEX('日次ログ'!$Z:$AO,0,$A33),"○")/J$24) | ... N33: =IF(N$24=0,"",COUNTIFS('日次ログ'!$A:$A,">="&N$23,'日次ログ'!$A:$A,"<="&EOMONTH(N$23,0),INDEX('日次ログ'!$Z:$AO,0,$A33),"○")/N$24)
A34: 10 | B34: ='毎日やること'!C14&"" | C34: =IF(C$24=0,"",COUNTIFS('日次ログ'!$A:$A,">="&C$23,'日次ログ'!$A:$A,"<="&EOMONTH(C$23,0),INDEX('日次ログ'!$Z:$AO,0,$A34),"○")/C$24) | D34: =IF(D$24=0,"",COUNTIFS('日次ログ'!$A:$A,">="&D$23,'日次ログ'!$A:$A,"<="&EOMONTH(D$23,0),INDEX('日次ログ'!$Z:$AO,0,$A34),"○")/D$24) | E34: =IF(E$24=0,"",COUNTIFS('日次ログ'!$A:$A,">="&E$23,'日次ログ'!$A:$A,"<="&EOMONTH(E$23,0),INDEX('日次ログ'!$Z:$AO,0,$A34),"○")/E$24) | F34: =IF(F$24=0,"",COUNTIFS('日次ログ'!$A:$A,">="&F$23,'日次ログ'!$A:$A,"<="&EOMONTH(F$23,0),INDEX('日次ログ'!$Z:$AO,0,$A34),"○")/F$24) | G34: =IF(G$24=0,"",COUNTIFS('日次ログ'!$A:$A,">="&G$23,'日次ログ'!$A:$A,"<="&EOMONTH(G$23,0),INDEX('日次ログ'!$Z:$AO,0,$A34),"○")/G$24) | H34: =IF(H$24=0,"",COUNTIFS('日次ログ'!$A:$A,">="&H$23,'日次ログ'!$A:$A,"<="&EOMONTH(H$23,0),INDEX('日次ログ'!$Z:$AO,0,$A34),"○")/H$24) | I34: =IF(I$24=0,"",COUNTIFS('日次ログ'!$A:$A,">="&I$23,'日次ログ'!$A:$A,"<="&EOMONTH(I$23,0),INDEX('日次ログ'!$Z:$AO,0,$A34),"○")/I$24) | J34: =IF(J$24=0,"",COUNTIFS('日次ログ'!$A:$A,">="&J$23,'日次ログ'!$A:$A,"<="&EOMONTH(J$23,0),INDEX('日次ログ'!$Z:$AO,0,$A34),"○")/J$24) | ... N34: =IF(N$24=0,"",COUNTIFS('日次ログ'!$A:$A,">="&N$23,'日次ログ'!$A:$A,"<="&EOMONTH(N$23,0),INDEX('日次ログ'!$Z:$AO,0,$A34),"○")/N$24)
A35: 11 | B35: ='毎日やること'!C15&"" | C35: =IF(C$24=0,"",COUNTIFS('日次ログ'!$A:$A,">="&C$23,'日次ログ'!$A:$A,"<="&EOMONTH(C$23,0),INDEX('日次ログ'!$Z:$AO,0,$A35),"○")/C$24) | D35: =IF(D$24=0,"",COUNTIFS('日次ログ'!$A:$A,">="&D$23,'日次ログ'!$A:$A,"<="&EOMONTH(D$23,0),INDEX('日次ログ'!$Z:$AO,0,$A35),"○")/D$24) | E35: =IF(E$24=0,"",COUNTIFS('日次ログ'!$A:$A,">="&E$23,'日次ログ'!$A:$A,"<="&EOMONTH(E$23,0),INDEX('日次ログ'!$Z:$AO,0,$A35),"○")/E$24) | F35: =IF(F$24=0,"",COUNTIFS('日次ログ'!$A:$A,">="&F$23,'日次ログ'!$A:$A,"<="&EOMONTH(F$23,0),INDEX('日次ログ'!$Z:$AO,0,$A35),"○")/F$24) | G35: =IF(G$24=0,"",COUNTIFS('日次ログ'!$A:$A,">="&G$23,'日次ログ'!$A:$A,"<="&EOMONTH(G$23,0),INDEX('日次ログ'!$Z:$AO,0,$A35),"○")/G$24) | H35: =IF(H$24=0,"",COUNTIFS('日次ログ'!$A:$A,">="&H$23,'日次ログ'!$A:$A,"<="&EOMONTH(H$23,0),INDEX('日次ログ'!$Z:$AO,0,$A35),"○")/H$24) | I35: =IF(I$24=0,"",COUNTIFS('日次ログ'!$A:$A,">="&I$23,'日次ログ'!$A:$A,"<="&EOMONTH(I$23,0),INDEX('日次ログ'!$Z:$AO,0,$A35),"○")/I$24) | J35: =IF(J$24=0,"",COUNTIFS('日次ログ'!$A:$A,">="&J$23,'日次ログ'!$A:$A,"<="&EOMONTH(J$23,0),INDEX('日次ログ'!$Z:$AO,0,$A35),"○")/J$24) | ... N35: =IF(N$24=0,"",COUNTIFS('日次ログ'!$A:$A,">="&N$23,'日次ログ'!$A:$A,"<="&EOMONTH(N$23,0),INDEX('日次ログ'!$Z:$AO,0,$A35),"○")/N$24)
A36: 12 | B36: ='毎日やること'!C16&"" | C36: =IF(C$24=0,"",COUNTIFS('日次ログ'!$A:$A,">="&C$23,'日次ログ'!$A:$A,"<="&EOMONTH(C$23,0),INDEX('日次ログ'!$Z:$AO,0,$A36),"○")/C$24) | D36: =IF(D$24=0,"",COUNTIFS('日次ログ'!$A:$A,">="&D$23,'日次ログ'!$A:$A,"<="&EOMONTH(D$23,0),INDEX('日次ログ'!$Z:$AO,0,$A36),"○")/D$24) | E36: =IF(E$24=0,"",COUNTIFS('日次ログ'!$A:$A,">="&E$23,'日次ログ'!$A:$A,"<="&EOMONTH(E$23,0),INDEX('日次ログ'!$Z:$AO,0,$A36),"○")/E$24) | F36: =IF(F$24=0,"",COUNTIFS('日次ログ'!$A:$A,">="&F$23,'日次ログ'!$A:$A,"<="&EOMONTH(F$23,0),INDEX('日次ログ'!$Z:$AO,0,$A36),"○")/F$24) | G36: =IF(G$24=0,"",COUNTIFS('日次ログ'!$A:$A,">="&G$23,'日次ログ'!$A:$A,"<="&EOMONTH(G$23,0),INDEX('日次ログ'!$Z:$AO,0,$A36),"○")/G$24) | H36: =IF(H$24=0,"",COUNTIFS('日次ログ'!$A:$A,">="&H$23,'日次ログ'!$A:$A,"<="&EOMONTH(H$23,0),INDEX('日次ログ'!$Z:$AO,0,$A36),"○")/H$24) | I36: =IF(I$24=0,"",COUNTIFS('日次ログ'!$A:$A,">="&I$23,'日次ログ'!$A:$A,"<="&EOMONTH(I$23,0),INDEX('日次ログ'!$Z:$AO,0,$A36),"○")/I$24) | J36: =IF(J$24=0,"",COUNTIFS('日次ログ'!$A:$A,">="&J$23,'日次ログ'!$A:$A,"<="&EOMONTH(J$23,0),INDEX('日次ログ'!$Z:$AO,0,$A36),"○")/J$24) | ... N36: =IF(N$24=0,"",COUNTIFS('日次ログ'!$A:$A,">="&N$23,'日次ログ'!$A:$A,"<="&EOMONTH(N$23,0),INDEX('日次ログ'!$Z:$AO,0,$A36),"○")/N$24)
... A40: 16 | B40: ='毎日やること'!C20&"" | C40: =IF(C$24=0,"",COUNTIFS('日次ログ'!$A:$A,">="&C$23,'日次ログ'!$A:$A,"<="&EOMONTH(C$23,0),INDEX('日次ログ'!$Z:$AO,0,$A40),"○")/C$24) | D40: =IF(D$24=0,"",COUNTIFS('日次ログ'!$A:$A,">="&D$23,'日次ログ'!$A:$A,"<="&EOMONTH(D$23,0),INDEX('日次ログ'!$Z:$AO,0,$A40),"○")/D$24) | E40: =IF(E$24=0,"",COUNTIFS('日次ログ'!$A:$A,">="&E$23,'日次ログ'!$A:$A,"<="&EOMONTH(E$23,0),INDEX('日次ログ'!$Z:$AO,0,$A40),"○")/E$24) | F40: =IF(F$24=0,"",COUNTIFS('日次ログ'!$A:$A,">="&F$23,'日次ログ'!$A:$A,"<="&EOMONTH(F$23,0),INDEX('日次ログ'!$Z:$AO,0,$A40),"○")/F$24) | G40: =IF(G$24=0,"",COUNTIFS('日次ログ'!$A:$A,">="&G$23,'日次ログ'!$A:$A,"<="&EOMONTH(G$23,0),INDEX('日次ログ'!$Z:$AO,0,$A40),"○")/G$24) | H40: =IF(H$24=0,"",COUNTIFS('日次ログ'!$A:$A,">="&H$23,'日次ログ'!$A:$A,"<="&EOMONTH(H$23,0),INDEX('日次ログ'!$Z:$AO,0,$A40),"○")/H$24) | I40: =IF(I$24=0,"",COUNTIFS('日次ログ'!$A:$A,">="&I$23,'日次ログ'!$A:$A,"<="&EOMONTH(I$23,0),INDEX('日次ログ'!$Z:$AO,0,$A40),"○")/I$24) | J40: =IF(J$24=0,"",COUNTIFS('日次ログ'!$A:$A,">="&J$23,'日次ログ'!$A:$A,"<="&EOMONTH(J$23,0),INDEX('日次ログ'!$Z:$AO,0,$A40),"○")/J$24) | ... N40: =IF(N$24=0,"",COUNTIFS('日次ログ'!$A:$A,">="&N$23,'日次ログ'!$A:$A,"<="&EOMONTH(N$23,0),INDEX('日次ログ'!$Z:$AO,0,$A40),"○")/N$24)

Sheet 10年計画
A1: 10年計画（年商1000億円からの逆算）
A2: 設定シートの「1年目の売上目標」と「10年目の売上目標」から、毎年同じ成長率で伸ばした場合の目標を計算する。実績は日次ログの売上高から自動で集計する。
A4: 1年目の売上目標 | B4: ='設定'!$B$6 | C4: 億円
A5: 10年目の売上目標 | B5: ='設定'!$B$7 | C5: 億円
A6: 必要な成長率（毎年） | B6: =IF(B4<=0,0,(B5/B4)^(1/9)-1) | C6: ％ | D6: この率で毎年伸ばすと、10年目に目標に届く（1年目から10年目までの9回分の成長）
A7: 10年目の1日あたり売上 | B7: =B5/365 | C7: 億円
A9: 年目 | B9: 期間開始 | C9: 期間終了 | D9: 売上目標（億円） | E9: 月平均（億円） | F9: 1日あたり（万円） | G9: 実績（億円） | H9: 達成率 | I9: 必要な受注件数（年） | J9: 必要な商談数（年） | K9: 必要な新規アプローチ数（年） | L9: 1日あたり必要なアプローチ数 | M9: 必要な営業担当者数（目安） | N9: 重点テーマ（例・書き換えてよい）
A10: 1 | B10: =EDATE('設定'!$B$5,12*(A10-1)) | C10: =EDATE('設定'!$B$5,12*A10)-1 | D10: =$B$4*(1+$B$6)^(A10-1) | E10: =D10/12 | F10: =D10*10^4/365 | G10: =SUMIFS('日次ログ'!$J:$J,'日次ログ'!$A:$A,">="&B10,'日次ログ'!$A:$A,"<="&C10)/10^8 | H10: =IF(D10=0,0,G10/D10) | I10: =IF('設定'!$B$8=0,0,D10*10^8/'設定'!$B$8) | J10: =IF('設定'!$B$9=0,0,I10/'設定'!$B$9) | K10: =IF('設定'!$B$10=0,0,J10/'設定'!$B$10) | L10: =K10/365 | M10: =IF('設定'!$B$11=0,0,L10/'設定'!$B$11) | N10: 再現できる売り方を確立する：顧客・商品・売り方を絞り込み、営業手順を文書にする
A11: 2 | B11: =EDATE('設定'!$B$5,12*(A11-1)) | C11: =EDATE('設定'!$B$5,12*A11)-1 | D11: =$B$4*(1+$B$6)^(A11-1) | E11: =D11/12 | F11: =D11*10^4/365 | G11: =SUMIFS('日次ログ'!$J:$J,'日次ログ'!$A:$A,">="&B11,'日次ログ'!$A:$A,"<="&C11)/10^8 | H11: =IF(D11=0,0,G11/D11) | I11: =IF('設定'!$B$8=0,0,D11*10^8/'設定'!$B$8) | J11: =IF('設定'!$B$9=0,0,I11/'設定'!$B$9) | K11: =IF('設定'!$B$10=0,0,J11/'設定'!$B$10) | L11: =K11/365 | M11: =IF('設定'!$B$11=0,0,L11/'設定'!$B$11) | N11: 売り方を人に移す：営業マニュアルを整え、最初の営業チームを採用する
A12: 3 | B12: =EDATE('設定'!$B$5,12*(A12-1)) | C12: =EDATE('設定'!$B$5,12*A12)-1 | D12: =$B$4*(1+$B$6)^(A12-1) | E12: =D12/12 | F12: =D12*10^4/365 | G12: =SUMIFS('日次ログ'!$J:$J,'日次ログ'!$A:$A,">="&B12,'日次ログ'!$A:$A,"<="&C12)/10^8 | H12: =IF(D12=0,0,G12/D12) | I12: =IF('設定'!$B$8=0,0,D12*10^8/'設定'!$B$8) | J12: =IF('設定'!$B$9=0,0,I12/'設定'!$B$9) | K12: =IF('設定'!$B$10=0,0,J12/'設定'!$B$10) | L12: =K12/365 | M12: =IF('設定'!$B$11=0,0,L12/'設定'!$B$11) | N12: 組織で売る：マネジャーを育て、KPIで管理する体制をつくる
A13: 4 | B13: =EDATE('設定'!$B$5,12*(A13-1)) | C13: =EDATE('設定'!$B$5,12*A13)-1 | D13: =$B$4*(1+$B$6)^(A13-1) | E13: =D13/12 | F13: =D13*10^4/365 | G13: =SUMIFS('日次ログ'!$J:$J,'日次ログ'!$A:$A,">="&B13,'日次ログ'!$A:$A,"<="&C13)/10^8 | H13: =IF(D13=0,0,G13/D13) | I13: =IF('設定'!$B$8=0,0,D13*10^8/'設定'!$B$8) | J13: =IF('設定'!$B$9=0,0,I13/'設定'!$B$9) | K13: =IF('設定'!$B$10=0,0,J13/'設定'!$B$10) | L13: =K13/365 | M13: =IF('設定'!$B$11=0,0,L13/'設定'!$B$11) | N13: 販路を増やす：マーケティング・紹介・パートナー経由の売上を増やす
A14: 5 | B14: =EDATE('設定'!$B$5,12*(A14-1)) | C14: =EDATE('設定'!$B$5,12*A14)-1 | D14: =$B$4*(1+$B$6)^(A14-1) | E14: =D14/12 | F14: =D14*10^4/365 | G14: =SUMIFS('日次ログ'!$J:$J,'日次ログ'!$A:$A,">="&B14,'日次ログ'!$A:$A,"<="&C14)/10^8 | H14: =IF(D14=0,0,G14/D14) | I14: =IF('設定'!$B$8=0,0,D14*10^8/'設定'!$B$8) | J14: =IF('設定'!$B$9=0,0,I14/'設定'!$B$9) | K14: =IF('設定'!$B$10=0,0,J14/'設定'!$B$10) | L14: =K14/365 | M14: =IF('設定'!$B$11=0,0,L14/'設定'!$B$11) | N14: 資金と管理体制：資金調達と管理部門を強化し、上場の準備を検討する
A15: 6 | B15: =EDATE('設定'!$B$5,12*(A15-1)) | C15: =EDATE('設定'!$B$5,12*A15)-1 | D15: =$B$4*(1+$B$6)^(A15-1) | E15: =D15/12 | F15: =D15*10^4/365 | G15: =SUMIFS('日次ログ'!$J:$J,'日次ログ'!$A:$A,">="&B15,'日次ログ'!$A:$A,"<="&C15)/10^8 | H15: =IF(D15=0,0,G15/D15) | I15: =IF('設定'!$B$8=0,0,D15*10^8/'設定'!$B$8) | J15: =IF('設定'!$B$9=0,0,I15/'設定'!$B$9) | K15: =IF('設定'!$B$10=0,0,J15/'設定'!$B$10) | L15: =K15/365 | M15: =IF('設定'!$B$11=0,0,L15/'設定'!$B$11) | N15: 2つ目の事業：新商品・新事業・新エリアに展開する
A16: 7 | B16: =EDATE('設定'!$B$5,12*(A16-1)) | C16: =EDATE('設定'!$B$5,12*A16)-1 | D16: =$B$4*(1+$B$6)^(A16-1) | E16: =D16/12 | F16: =D16*10^4/365 | G16: =SUMIFS('日次ログ'!$J:$J,'日次ログ'!$A:$A,">="&B16,'日次ログ'!$A:$A,"<="&C16)/10^8 | H16: =IF(D16=0,0,G16/D16) | I16: =IF('設定'!$B$8=0,0,D16*10^8/'設定'!$B$8) | J16: =IF('設定'!$B$9=0,0,I16/'設定'!$B$9) | K16: =IF('設定'!$B$10=0,0,J16/'設定'!$B$10) | L16: =K16/365 | M16: =IF('設定'!$B$11=0,0,L16/'設定'!$B$11) | N16: M&Aと提携：買収や提携で顧客・人材・商品を増やす
A17: 8 | B17: =EDATE('設定'!$B$5,12*(A17-1)) | C17: =EDATE('設定'!$B$5,12*A17)-1 | D17: =$B$4*(1+$B$6)^(A17-1) | E17: =D17/12 | F17: =D17*10^4/365 | G17: =SUMIFS('日次ログ'!$J:$J,'日次ログ'!$A:$A,">="&B17,'日次ログ'!$A:$A,"<="&C17)/10^8 | H17: =IF(D17=0,0,G17/D17) | I17: =IF('設定'!$B$8=0,0,D17*10^8/'設定'!$B$8) | J17: =IF('設定'!$B$9=0,0,I17/'設定'!$B$9) | K17: =IF('設定'!$B$10=0,0,J17/'設定'!$B$10) | L17: =K17/365 | M17: =IF('設定'!$B$11=0,0,L17/'設定'!$B$11) | N17: 経営チーム：事業ごとに責任者を置き、自分は方針と資本政策に集中する
A18: 9 | B18: =EDATE('設定'!$B$5,12*(A18-1)) | C18: =EDATE('設定'!$B$5,12*A18)-1 | D18: =$B$4*(1+$B$6)^(A18-1) | E18: =D18/12 | F18: =D18*10^4/365 | G18: =SUMIFS('日次ログ'!$J:$J,'日次ログ'!$A:$A,">="&B18,'日次ログ'!$A:$A,"<="&C18)/10^8 | H18: =IF(D18=0,0,G18/D18) | I18: =IF('設定'!$B$8=0,0,D18*10^8/'設定'!$B$8) | J18: =IF('設定'!$B$9=0,0,I18/'設定'!$B$9) | K18: =IF('設定'!$B$10=0,0,J18/'設定'!$B$10) | L18: =K18/365 | M18: =IF('設定'!$B$11=0,0,L18/'設定'!$B$11) | N18: 複数事業で伸ばす：事業の組み合わせで成長を続け、1つの市場の不振に左右されにくくする
A19: 10 | B19: =EDATE('設定'!$B$5,12*(A19-1)) | C19: =EDATE('設定'!$B$5,12*A19)-1 | D19: =$B$4*(1+$B$6)^(A19-1) | E19: =D19/12 | F19: =D19*10^4/365 | G19: =SUMIFS('日次ログ'!$J:$J,'日次ログ'!$A:$A,">="&B19,'日次ログ'!$A:$A,"<="&C19)/10^8 | H19: =IF(D19=0,0,G19/D19) | I19: =IF('設定'!$B$8=0,0,D19*10^8/'設定'!$B$8) | J19: =IF('設定'!$B$9=0,0,I19/'設定'!$B$9) | K19: =IF('設定'!$B$10=0,0,J19/'設定'!$B$10) | L19: =K19/365 | M19: =IF('設定'!$B$11=0,0,L19/'設定'!$B$11) | N19: 年商1000億円：次の10年の方針を決める
A21: 必要な件数は、設定シートの平均受注単価・受注率・商談化率から計算する。単価や転換率が上がると、必要な件数と人数は減る。年商が大きくなるほど、1人の行動量ではなく、組織・単価・販路で売上をつくる必要があることがわかる。

Sheet 日次ログ
A1: 基本情報 | F1: 今日のTop3の結果 | J1: 日次決算（円） | R1: 営業実績 | Z1: 1000億への日課（○△×） | AQ1: 振り返り | AV1: 明日の計画 | AZ1: 提出
A2: 日付 | B2: 曜日 | C2: 計画年目 | D2: 体調 | E2: 今日のテーマ | F2: Top3①結果 | G2: Top3②結果 | H2: Top3③結果 | I2: Top3実行率 | J2: 売上高 | K2: 売上原価 | L2: 粗利 | M2: 販管費 | N2: 営業利益 | O2: 入金額 | P2: 出金額 | Q2: 現預金残高 | R2: 新規アプローチ | S2: アポ獲得 | T2: 商談 | U2: 提案・見積 | V2: 受注数 | W2: 受注金額 | X2: 既存顧客接点 | Y2: 紹介獲得 | Z2: ='毎日やること'!$A$5&" "&'毎日やること'!$D$5 | AA2: ='毎日やること'!$A$6&" "&'毎日やること'!$D$6 | AB2: ='毎日やること'!$A$7&" "&'毎日やること'!$D$7 | AC2: ='毎日やること'!$A$8&" "&'毎日やること'!$D$8 | AD2: ='毎日やること'!$A$9&" "&'毎日やること'!$D$9 | AE2: ='毎日やること'!$A$10&" "&'毎日やること'!$D$10 | AF2: ='毎日やること'!$A$11&" "&'毎日やること'!$D$11 | AG2: ='毎日やること'!$A$12&" "&'毎日やること'!$D$12 | AH2: ='毎日やること'!$A$13&" "&'毎日やること'!$D$13 | AI2: ='毎日やること'!$A$14&" "&'毎日やること'!$D$14 | AJ2: ='毎日やること'!$A$15&" "&'毎日やること'!$D$15 | AK2: ='毎日やること'!$A$16&" "&'毎日やること'!$D$16 | AL2: ='毎日やること'!$A$17&" "&'毎日やること'!$D$17 | AM2: ='毎日やること'!$A$18&" "&'毎日やること'!$D$18 | AN2: ='毎日やること'!$A$19&" "&'毎日やること'!$D$19 | AO2: ='毎日やること'!$A$20&" "&'毎日やること'!$D$20 | AP2: 日課達成率 | AQ2: 今日の成果 | AR2: Keep | AS2: Problem | AT2: Try | AU2: 学び・気づき | AV2: 明日のTop3① | AW2: 明日のTop3② | AX2: 明日のTop3③ | AY2: 相談・決めること | AZ2: 提出日時
A3: 記入例 | B3: 木 | C3: 1 | D3: 4 | E3: 新規開拓に集中する日 | F3: ○ | G3: ○ | H3: △ | I3: 0.66666667 | J3: 300000 | K3: 90000 | L3: 210000 | M3: 25000 | N3: 185000 | O3: 500000 | P3: 120000 | Q3: 3200000 | R3: 35 | S3: 4 | T3: 3 | U3: 2 | V3: 1 | W3: 500000 | X3: 2 | Y3: 1 | Z3: ○ | AA3: ○ | AB3: ○ | AC3: ○ | AD3: △ | AE3: ○ | AF3: ○ | AG3: × | AH3: ○ | AI3: △ | AJ3: ○ | AK3: ○ | AL3: × | AM3: ○ | AN3: ○ | AO3: ○ | AP3: 0.75 | AQ3: 新規1件受注（50万円） | AR3: 午前中に架電をまとめたらアポ率が上がった | AS3: 見積の作成に2時間かかった | AT3: 見積のテンプレートを作る | AU3: 決裁者が同席すると商談が早く進む | AV3: A社に提案書を送る | AW3: 営業トークをマニュアルにする | AX3: 採用候補者と面談

Sheet 提出データ
A1: 日付 | B1: 曜日 | C1: 計画年目 | D1: 体調 | E1: 今日のテーマ | F1: Top3①結果 | G1: Top3②結果 | H1: Top3③結果 | I1: Top3実行率 | J1: 売上高 | K1: 売上原価 | L1: 粗利 | M1: 販管費 | N1: 営業利益 | O1: 入金額 | P1: 出金額 | Q1: 現預金残高 | R1: 新規アプローチ | S1: アポ獲得 | T1: 商談 | U1: 提案・見積 | V1: 受注数 | W1: 受注金額 | X1: 既存顧客接点 | Y1: 紹介獲得 | Z1: ='毎日やること'!$A$5&" "&'毎日やること'!$D$5 | AA1: ='毎日やること'!$A$6&" "&'毎日やること'!$D$6 | AB1: ='毎日やること'!$A$7&" "&'毎日やること'!$D$7 | AC1: ='毎日やること'!$A$8&" "&'毎日やること'!$D$8 | AD1: ='毎日やること'!$A$9&" "&'毎日やること'!$D$9 | AE1: ='毎日やること'!$A$10&" "&'毎日やること'!$D$10 | AF1: ='毎日やること'!$A$11&" "&'毎日やること'!$D$11 | AG1: ='毎日やること'!$A$12&" "&'毎日やること'!$D$12 | AH1: ='毎日やること'!$A$13&" "&'毎日やること'!$D$13 | AI1: ='毎日やること'!$A$14&" "&'毎日やること'!$D$14 | AJ1: ='毎日やること'!$A$15&" "&'毎日やること'!$D$15 | AK1: ='毎日やること'!$A$16&" "&'毎日やること'!$D$16 | AL1: ='毎日やること'!$A$17&" "&'毎日やること'!$D$17 | AM1: ='毎日やること'!$A$18&" "&'毎日やること'!$D$18 | AN1: ='毎日やること'!$A$19&" "&'毎日やること'!$D$19 | AO1: ='毎日やること'!$A$20&" "&'毎日やること'!$D$20 | AP1: 日課達成率 | AQ1: 今日の成果 | AR1: Keep | AS1: Problem | AT1: Try | AU1: 学び・気づき | AV1: 明日のTop3① | AW1: 明日のTop3② | AX1: 明日のTop3③ | AY1: 相談・決めること | AZ1: 提出日時
A2: ='本日の日報'!B5 | B2: ='本日の日報'!C5 | C2: ='本日の日報'!B6 | D2: =IF('本日の日報'!B7="","",'本日の日報'!B7) | E2: ='本日の日報'!B8&"" | F2: ='本日の日報'!B12&"" | G2: ='本日の日報'!B13&"" | H2: ='本日の日報'!B14&"" | I2: ='本日の日報'!B15 | J2: ='本日の日報'!B38 | K2: ='本日の日報'!B39 | L2: ='本日の日報'!B40 | M2: ='本日の日報'!B42 | N2: ='本日の日報'!B43 | O2: ='本日の日報'!B48 | P2: ='本日の日報'!B49 | Q2: =IF('本日の日報'!B51="","",'本日の日報'!B51) | R2: ='本日の日報'!B27 | S2: ='本日の日報'!B28 | T2: ='本日の日報'!B29 | U2: ='本日の日報'!B30 | V2: ='本日の日報'!B31 | W2: ='本日の日報'!B32 | X2: ='本日の日報'!B33 | Y2: ='本日の日報'!B34 | Z2: ='本日の日報'!B56&"" | AA2: ='本日の日報'!B57&"" | AB2: ='本日の日報'!B58&"" | AC2: ='本日の日報'!B59&"" | AD2: ='本日の日報'!B60&"" | AE2: ='本日の日報'!B61&"" | AF2: ='本日の日報'!B62&"" | AG2: ='本日の日報'!B63&"" | AH2: ='本日の日報'!B64&"" | AI2: ='本日の日報'!B65&"" | AJ2: ='本日の日報'!B66&"" | AK2: ='本日の日報'!B67&"" | AL2: ='本日の日報'!B68&"" | AM2: ='本日の日報'!B69&"" | AN2: ='本日の日報'!B70&"" | AO2: ='本日の日報'!B71&"" | AP2: ='本日の日報'!B72 | AQ2: ='本日の日報'!B75&"" | AR2: ='本日の日報'!B76&"" | AS2: ='本日の日報'!B77&"" | AT2: ='本日の日報'!B78&"" | AU2: ='本日の日報'!B79&"" | AV2: ='本日の日報'!B80&"" | AW2: ='本日の日報'!B81&"" | AX2: ='本日の日報'!B82&"" | AY2: ='本日の日報'!B83&"" | AZ2: =NOW()
A4: このシートは自動作成（編集しない）。Apps Scriptの「本日の日報を提出」は、この2行目を日次ログに書き込む。スクリプトを使わない場合は、2行目（A2〜AZ2）をコピーし、「日次ログ」の最終行の下に値のみ貼り付け（Ctrl+Shift+V）する。日付が数字で表示されたら、日次ログのA列を選んで「表示形式」→「数字」→「日付」にする。

Sheet 設定
A1: 設定（目標・前提条件・選択肢）
A2: 薄い黄色のセルを自分の数字に書き換える。ほかのシートの計算はすべてここを参照している。
A4: 項目 | B4: 値 | C4: 単位 | D4: メモ（出所） | F4: 勘定科目 | I4: 支払方法 | K4: 案件フェーズ | L4: 確度
A5: 計画開始日 | B5: 46296 | C5: 日付 | D5: 仮の値：1年目の初日。変更すると10年計画と月次集計の期間が連動する | F5: 原価：仕入高 | I5: 現金 | K5: リード | L5: 0.05
A6: 1年目の売上目標 | B6: 2 | C6: 億円 | D6: 仮の値：現状の売上から見て現実的な1年目の目標に変更する | F6: 原価：外注費 | I6: クレジットカード | K6: アポ獲得 | L6: 0.1
A7: 10年目の売上目標 | B7: 1000 | C7: 億円 | D7: 出所：ご本人の目標（10年後に年商1000億円） | F7: 販管費：広告宣伝費 | I7: 銀行振込 | K7: 商談中 | L7: 0.25
A8: 平均受注単価（想定） | B8: 500000 | C8: 円 | D8: 仮の値：直近の受注実績の平均に変更する | F8: 販管費：旅費交通費 | I8: 口座引落 | K8: 提案済 | L8: 0.5
A9: 商談からの受注率（想定） | B9: 0.3 | C9: ％ | D9: 仮の値：直近の実績（受注数÷商談数）に変更する | F9: 販管費：交際費 | I9: 電子マネー・QR | K9: 交渉中 | L9: 0.75
A10: アプローチからの商談化率（想定） | B10: 0.1 | C10: ％ | D10: 仮の値：直近の実績（商談数÷新規アプローチ数）に変更する | F10: 販管費：会議費 | I10: その他 | K10: 受注 | L10: 1
A11: 営業1人が1日にできるアプローチ数 | B11: 50 | C11: 件 | D11: 仮の値：10年計画の「必要な営業担当者数」の計算に使う | F11: 販管費：通信費 | K11: 失注 | L11: 0
A12: 既存顧客との接点（1日の目標） | B12: 1 | C12: 社 | D12: 毎日やることNo.5の目安 | F12: 販管費：消耗品費 | K12: 保留 | L12: 0
A13: 記入者 | D13: 自分の名前（本日の日報と提出メールに表示） | F13: 販管費：地代家賃 | K13: 確度は仮の値。フェーズ別の加重見込金額（案件パイプライン）に使う。
A14: 提出先メールアドレス | D14: Apps Scriptで提出したときにメールを送る宛先。空欄なら送らない | F14: 販管費：水道光熱費
A15: リマインドの時刻 | B15: 21 | C15: 時 | D15: Apps Scriptの「毎日のリマインドを設定」で、未提出を知らせる時刻（0〜23） | F15: 販管費：支払手数料
F16: 販管費：新聞図書費
F17: 販管費：採用教育費
F18: 販管費：給与・人件費
F19: 販管費：福利厚生費
F20: 販管費：保険料
F21: 販管費：租税公課
F22: 販管費：雑費
F31: 「原価：」で始まる科目は売上原価、それ以外は販管費として集計する。空いている行に科目を追加できる（例：原価：材料費）。
